Watching for file changes with StatReloader
[20/Jul/2023 09:43:51] "GET / HTTP/1.1" 200 1515
[20/Jul/2023 09:43:51] "GET /staticfiles/css/main.css HTTP/1.1" 304 0
[20/Jul/2023 09:43:51] "GET /staticfiles/css/botones.css HTTP/1.1" 304 0
[20/Jul/2023 09:43:51] "GET /staticfiles/css/estilos.css HTTP/1.1" 200 5547
C:\Users\administrator\Documents\NTTCS_Control_Framework\NTTCS_CF_project\homepage\views.py changed, reloading.
Performing system checks...

System check identified no issues (0 silenced).
July 20, 2023 - 09:43:51
Django version 4.2.2, using settings 'NTTCS_CF_project.settings'
Starting development server at http://127.0.0.1:9242/
Quit the server with CTRL-BREAK.

Watching for file changes with StatReloader
Internal Server Error: /MantenimientoAssessmentArchivados/
Traceback (most recent call last):
  File "C:\Users\administrator\AppData\Local\Programs\Python\Python311\Lib\site-packages\django\core\handlers\exception.py", line 55, in inner
    response = get_response(request)
               ^^^^^^^^^^^^^^^^^^^^^
  File "C:\Users\administrator\AppData\Local\Programs\Python\Python311\Lib\site-packages\django\core\handlers\base.py", line 197, in _get_response
    response = wrapped_callback(request, *callback_args, **callback_kwargs)
               ^^^^^^^^^^^^^^^^^^^^^^^^^^^^^^^^^^^^^^^^^^^^^^^^^^^^^^^^^^^^
  File "C:\Users\administrator\AppData\Local\Programs\Python\Python311\Lib\site-packages\django\views\generic\base.py", line 104, in view
    return self.dispatch(request, *args, **kwargs)
           ^^^^^^^^^^^^^^^^^^^^^^^^^^^^^^^^^^^^^^^
  File "C:\Users\administrator\AppData\Local\Programs\Python\Python311\Lib\site-packages\django\contrib\auth\mixins.py", line 73, in dispatch
    return super().dispatch(request, *args, **kwargs)
           ^^^^^^^^^^^^^^^^^^^^^^^^^^^^^^^^^^^^^^^^^^
  File "C:\Users\administrator\AppData\Local\Programs\Python\Python311\Lib\site-packages\django\views\generic\base.py", line 143, in dispatch
    return handler(request, *args, **kwargs)
           ^^^^^^^^^^^^^^^^^^^^^^^^^^^^^^^^^
  File "C:\Users\administrator\AppData\Local\Programs\Python\Python311\Lib\site-packages\django\views\generic\base.py", line 226, in get
    context = self.get_context_data(**kwargs)
              ^^^^^^^^^^^^^^^^^^^^^^^^^^^^^^^
  File "C:\Users\administrator\Documents\NTTCS_Control_Framework\NTTCS_CF_project\homepage\views.py", line 1146, in get_context_data
    s = Assessmentguardados.objects.get(archivado=1)
        ^^^^^^^^^^^^^^^^^^^^^^^^^^^^^^^^^^^^^^^^^^^^
  File "C:\Users\administrator\AppData\Local\Programs\Python\Python311\Lib\site-packages\django\db\models\manager.py", line 87, in manager_method
    return getattr(self.get_queryset(), name)(*args, **kwargs)
           ^^^^^^^^^^^^^^^^^^^^^^^^^^^^^^^^^^^^^^^^^^^^^^^^^^^
  File "C:\Users\administrator\AppData\Local\Programs\Python\Python311\Lib\site-packages\django\db\models\query.py", line 637, in get
    raise self.model.DoesNotExist(
homepage.models.Assessmentguardados.DoesNotExist: Assessmentguardados matching query does not exist.
[20/Jul/2023 09:48:12] "GET /MantenimientoAssessmentArchivados/ HTTP/1.1" 500 89412
[20/Jul/2023 09:48:15] "GET /menu/ HTTP/1.1" 200 9360
[20/Jul/2023 09:48:18] "GET /exportaciones/ HTTP/1.1" 200 11422
[20/Jul/2023 09:48:30] "POST /exportaciones/ HTTP/1.1" 200 2641779
[20/Jul/2023 09:51:55] "GET /exportaciones/ HTTP/1.1" 200 11304
[20/Jul/2023 09:51:55] "GET /staticfiles/css/estilos.css HTTP/1.1" 200 5831
[20/Jul/2023 09:51:59] "GET /assessmentselect/ HTTP/1.1" 200 21138
[20/Jul/2023 09:52:22] "POST / HTTP/1.1" 302 0
[20/Jul/2023 09:52:22] "GET /menu/ HTTP/1.1" 200 9360
[20/Jul/2023 09:52:22] "GET /staticfiles/css/ass.css HTTP/1.1" 304 0
[20/Jul/2023 09:52:22] "GET /staticfiles/js/scripts.js HTTP/1.1" 304 0
[20/Jul/2023 09:52:22] "GET /staticfiles/images/equipo2.jpg HTTP/1.1" 304 0
[20/Jul/2023 09:52:37] "GET /admin HTTP/1.1" 301 0
[20/Jul/2023 09:52:38] "GET /admin/ HTTP/1.1" 200 8759
[20/Jul/2023 09:52:38] "GET /staticfiles/admin/css/dark_mode.css HTTP/1.1" 200 2929
[20/Jul/2023 09:52:38] "GET /staticfiles/admin/css/base.css HTTP/1.1" 200 21207
[20/Jul/2023 09:52:38] "GET /staticfiles/admin/js/theme.js HTTP/1.1" 200 1943
[20/Jul/2023 09:52:38] "GET /staticfiles/admin/css/nav_sidebar.css HTTP/1.1" 200 2694
[20/Jul/2023 09:52:38] "GET /staticfiles/admin/css/dashboard.css HTTP/1.1" 200 441
[20/Jul/2023 09:52:38] "GET /staticfiles/admin/js/nav_sidebar.js HTTP/1.1" 200 3063
[20/Jul/2023 09:52:38] "GET /staticfiles/admin/css/responsive.css HTTP/1.1" 200 18533
[20/Jul/2023 09:52:38] "GET /staticfiles/admin/img/icon-changelink.svg HTTP/1.1" 200 380
[20/Jul/2023 09:52:38] "GET /staticfiles/admin/img/icon-deletelink.svg HTTP/1.1" 200 392
[20/Jul/2023 09:52:38] "GET /staticfiles/admin/img/icon-addlink.svg HTTP/1.1" 200 331
[20/Jul/2023 09:52:55] "GET /admin/auth/group/ HTTP/1.1" 200 9253
[20/Jul/2023 09:52:56] "GET /staticfiles/admin/css/changelists.css HTTP/1.1" 200 6584
[20/Jul/2023 09:52:56] "GET /staticfiles/admin/js/core.js HTTP/1.1" 200 5682
[20/Jul/2023 09:52:56] "GET /staticfiles/admin/js/admin/RelatedObjectLookups.js HTTP/1.1" 200 8943
[20/Jul/2023 09:52:56] "GET /staticfiles/admin/js/jquery.init.js HTTP/1.1" 200 347
[20/Jul/2023 09:52:56] "GET /admin/jsi18n/ HTTP/1.1" 200 8006
[20/Jul/2023 09:52:56] "GET /staticfiles/admin/js/vendor/jquery/jquery.js HTTP/1.1" 200 292458
[20/Jul/2023 09:52:56] "GET /staticfiles/admin/js/actions.js HTTP/1.1" 200 7872
[20/Jul/2023 09:52:56] "GET /staticfiles/admin/js/urlify.js HTTP/1.1" 200 7887
[20/Jul/2023 09:52:56] "GET /staticfiles/admin/js/prepopulate.js HTTP/1.1" 200 1531
[20/Jul/2023 09:52:56] "GET /staticfiles/admin/js/vendor/xregexp/xregexp.js HTTP/1.1" 200 232381
[20/Jul/2023 09:52:56] "GET /staticfiles/admin/js/filters.js HTTP/1.1" 200 978
[20/Jul/2023 09:52:57] "GET /staticfiles/admin/img/search.svg HTTP/1.1" 200 458
[20/Jul/2023 09:52:57] "GET /staticfiles/admin/img/tooltag-add.svg HTTP/1.1" 200 331
[20/Jul/2023 09:53:14] "GET /admin/auth/group/add/ HTTP/1.1" 200 18736
[20/Jul/2023 09:53:14] "GET /staticfiles/admin/css/forms.css HTTP/1.1" 200 8953
[20/Jul/2023 09:53:14] "GET /admin/jsi18n/ HTTP/1.1" 200 8006
[20/Jul/2023 09:53:14] "GET /staticfiles/admin/js/SelectBox.js HTTP/1.1" 200 4530
[20/Jul/2023 09:53:14] "GET /staticfiles/admin/js/SelectFilter2.js HTTP/1.1" 200 15292
[20/Jul/2023 09:53:14] "GET /staticfiles/admin/js/prepopulate_init.js HTTP/1.1" 200 586
[20/Jul/2023 09:53:14] "GET /staticfiles/admin/js/change_form.js HTTP/1.1" 200 606
[20/Jul/2023 09:53:14] "GET /staticfiles/admin/css/widgets.css HTTP/1.1" 200 11900
[20/Jul/2023 09:53:14] "GET /staticfiles/admin/img/selector-icons.svg HTTP/1.1" 200 3291
[20/Jul/2023 09:53:14] "GET /staticfiles/admin/img/icon-unknown.svg HTTP/1.1" 200 655
[20/Jul/2023 09:53:14] "GET /staticfiles/admin/img/icon-unknown-alt.svg HTTP/1.1" 200 655
[20/Jul/2023 09:53:46] "GET /admin/acounts/user/ HTTP/1.1" 200 9552
[20/Jul/2023 09:53:46] "GET /admin/jsi18n/ HTTP/1.1" 200 8006
[20/Jul/2023 09:53:52] "GET /admin/acounts/user/23/change/ HTTP/1.1" 200 28047
[20/Jul/2023 09:53:52] "GET /staticfiles/admin/js/calendar.js HTTP/1.1" 200 8466
[20/Jul/2023 09:53:52] "GET /staticfiles/admin/js/admin/DateTimeShortcuts.js HTTP/1.1" 200 19319
[20/Jul/2023 09:53:52] "GET /admin/jsi18n/ HTTP/1.1" 200 8006
[20/Jul/2023 09:53:52] "GET /staticfiles/admin/img/icon-calendar.svg HTTP/1.1" 200 1086
[20/Jul/2023 09:53:52] "GET /staticfiles/admin/img/icon-clock.svg HTTP/1.1" 200 677
[20/Jul/2023 09:54:23] "GET / HTTP/1.1" 200 1515
[20/Jul/2023 09:55:04] "POST / HTTP/1.1" 302 0
[20/Jul/2023 09:55:04] "GET /menu/ HTTP/1.1" 200 9360
[20/Jul/2023 09:55:04] "GET /staticfiles/images/equipo2.jpg HTTP/1.1" 200 16151
[20/Jul/2023 09:55:07] "GET /usuarios/ HTTP/1.1" 200 15482
[20/Jul/2023 09:55:35] "POST /usuarios/ HTTP/1.1" 200 15690
[20/Jul/2023 09:55:45] "POST /usuarios/ HTTP/1.1" 200 19554
[20/Jul/2023 09:55:52] "GET /accounts/logout/ HTTP/1.1" 302 0
[20/Jul/2023 09:55:52] "GET / HTTP/1.1" 200 1515
[20/Jul/2023 09:56:03] "POST / HTTP/1.1" 200 1515
[20/Jul/2023 09:56:12] "POST / HTTP/1.1" 302 0
[20/Jul/2023 09:56:12] "GET /creacionPass/ HTTP/1.1" 200 6161
[20/Jul/2023 09:56:28] "POST /creacionPass/ HTTP/1.1" 200 6485
[20/Jul/2023 09:56:45] "POST /creacionPass/ HTTP/1.1" 200 6534
[20/Jul/2023 09:57:09] "GET /accounts/logout/ HTTP/1.1" 302 0
[20/Jul/2023 09:57:09] "GET / HTTP/1.1" 200 1515
[20/Jul/2023 09:57:10] "GET /staticfiles/css/estilos.css HTTP/1.1" 304 0
[20/Jul/2023 09:57:18] "POST / HTTP/1.1" 302 0
[20/Jul/2023 09:57:18] "GET /menu/ HTTP/1.1" 200 9360
[20/Jul/2023 09:57:20] "POST /creacionPass/ HTTP/1.1" 200 6534
[20/Jul/2023 09:57:46] "POST /creacionPass/ HTTP/1.1" 302 0
[20/Jul/2023 09:57:46] "GET /accounts/logout/ HTTP/1.1" 302 0
[20/Jul/2023 09:57:46] "GET / HTTP/1.1" 200 1793
[20/Jul/2023 09:58:08] "POST / HTTP/1.1" 302 0
[20/Jul/2023 09:58:08] "GET /menu/ HTTP/1.1" 200 9360
[20/Jul/2023 09:58:08] "GET /staticfiles/images/equipo2.jpg HTTP/1.1" 200 16151
[20/Jul/2023 09:58:19] "GET /assessmentselect/ HTTP/1.1" 200 21138
[20/Jul/2023 09:58:49] "GET /assessmentselect/ HTTP/1.1" 200 21138
[20/Jul/2023 09:58:49] "GET /staticfiles/css/estilos.css HTTP/1.1" 304 0
[20/Jul/2023 09:59:18] "POST /assessmentselect/ HTTP/1.1" 302 0
[20/Jul/2023 09:59:18] "GET /assessment/ HTTP/1.1" 200 46824
[20/Jul/2023 09:59:46] "POST /assessment/ HTTP/1.1" 200 57301
[20/Jul/2023 09:59:50] "POST /assessmentselect/ HTTP/1.1" 302 0
Internal Server Error: /assessment/
Traceback (most recent call last):
  File "C:\Users\administrator\AppData\Local\Programs\Python\Python311\Lib\site-packages\mysql\connector\connection_cext.py", line 416, in get_rows
    row = fetch_row()
          ^^^^^^^^^^^
_mysql_connector.MySQLInterfaceError: Table definition has changed, please retry transaction

The above exception was the direct cause of the following exception:

Traceback (most recent call last):
  File "C:\Users\administrator\AppData\Local\Programs\Python\Python311\Lib\site-packages\django\core\handlers\exception.py", line 55, in inner
    response = get_response(request)
               ^^^^^^^^^^^^^^^^^^^^^
  File "C:\Users\administrator\AppData\Local\Programs\Python\Python311\Lib\site-packages\django\core\handlers\base.py", line 197, in _get_response
    response = wrapped_callback(request, *callback_args, **callback_kwargs)
               ^^^^^^^^^^^^^^^^^^^^^^^^^^^^^^^^^^^^^^^^^^^^^^^^^^^^^^^^^^^^
  File "C:\Users\administrator\AppData\Local\Programs\Python\Python311\Lib\site-packages\django\views\generic\base.py", line 104, in view
    return self.dispatch(request, *args, **kwargs)
           ^^^^^^^^^^^^^^^^^^^^^^^^^^^^^^^^^^^^^^^
  File "C:\Users\administrator\AppData\Local\Programs\Python\Python311\Lib\site-packages\django\contrib\auth\mixins.py", line 73, in dispatch
    return super().dispatch(request, *args, **kwargs)
           ^^^^^^^^^^^^^^^^^^^^^^^^^^^^^^^^^^^^^^^^^^
  File "C:\Users\administrator\AppData\Local\Programs\Python\Python311\Lib\site-packages\django\views\generic\base.py", line 143, in dispatch
    return handler(request, *args, **kwargs)
           ^^^^^^^^^^^^^^^^^^^^^^^^^^^^^^^^^
  File "C:\Users\administrator\AppData\Local\Programs\Python\Python311\Lib\site-packages\django\views\generic\base.py", line 226, in get
    context = self.get_context_data(**kwargs)
              ^^^^^^^^^^^^^^^^^^^^^^^^^^^^^^^
  File "C:\Users\administrator\Documents\NTTCS_Control_Framework\NTTCS_CF_project\homepage\views.py", line 280, in get_context_data
    mycursor.execute("SELECT * FROM " + assSelect)
  File "C:\Users\administrator\AppData\Local\Programs\Python\Python311\Lib\site-packages\mysql\connector\cursor_cext.py", line 342, in execute
    self._handle_result(result)
  File "C:\Users\administrator\AppData\Local\Programs\Python\Python311\Lib\site-packages\mysql\connector\cursor_cext.py", line 230, in _handle_result
    self._handle_resultset()
  File "C:\Users\administrator\AppData\Local\Programs\Python\Python311\Lib\site-packages\mysql\connector\cursor_cext.py", line 788, in _handle_resultset
    self._rows = self._cnx.get_rows()[0]
                 ^^^^^^^^^^^^^^^^^^^^
  File "C:\Users\administrator\AppData\Local\Programs\Python\Python311\Lib\site-packages\mysql\connector\connection_cext.py", line 445, in get_rows
    raise get_mysql_exception(
mysql.connector.errors.DatabaseError: 1412 (HY000): Table definition has changed, please retry transaction
[20/Jul/2023 09:59:50] "GET /assessment/ HTTP/1.1" 500 105289
[20/Jul/2023 10:00:02] "GET /assessmentselect/ HTTP/1.1" 200 21358
[20/Jul/2023 10:01:19] "POST /assessment/ HTTP/1.1" 200 57500
[20/Jul/2023 10:03:14] "POST /assessmentselect/ HTTP/1.1" 302 0
[20/Jul/2023 10:03:14] "GET /assessment/ HTTP/1.1" 200 86875
[20/Jul/2023 10:03:14] "GET /staticfiles/css/estilos.css HTTP/1.1" 304 0
[20/Jul/2023 10:03:36] "POST /assessment/ HTTP/1.1" 302 0
[20/Jul/2023 10:03:36] "GET /menu/ HTTP/1.1" 200 9360
[20/Jul/2023 10:03:36] "POST /assessment/ HTTP/1.1" 200 57615
[20/Jul/2023 10:03:40] "GET /MantenimientoAssessmentArchivados/ HTTP/1.1" 200 9931
[20/Jul/2023 10:03:42] "POST /MantenimientoAssessmentArchivados/ HTTP/1.1" 200 3441952
[20/Jul/2023 10:03:45] "POST /assessment/ HTTP/1.1" 200 57930
[20/Jul/2023 10:03:57] "POST /assessment/ HTTP/1.1" 200 57373
Internal Server Error: /MantenimientoAssessmentArchivados/
Traceback (most recent call last):
  File "C:\Users\administrator\AppData\Local\Programs\Python\Python311\Lib\site-packages\django\core\handlers\exception.py", line 55, in inner
    response = get_response(request)
               ^^^^^^^^^^^^^^^^^^^^^
  File "C:\Users\administrator\AppData\Local\Programs\Python\Python311\Lib\site-packages\django\core\handlers\base.py", line 197, in _get_response
    response = wrapped_callback(request, *callback_args, **callback_kwargs)
               ^^^^^^^^^^^^^^^^^^^^^^^^^^^^^^^^^^^^^^^^^^^^^^^^^^^^^^^^^^^^
  File "C:\Users\administrator\AppData\Local\Programs\Python\Python311\Lib\site-packages\django\views\generic\base.py", line 104, in view
    return self.dispatch(request, *args, **kwargs)
           ^^^^^^^^^^^^^^^^^^^^^^^^^^^^^^^^^^^^^^^
  File "C:\Users\administrator\AppData\Local\Programs\Python\Python311\Lib\site-packages\django\contrib\auth\mixins.py", line 73, in dispatch
    return super().dispatch(request, *args, **kwargs)
           ^^^^^^^^^^^^^^^^^^^^^^^^^^^^^^^^^^^^^^^^^^
  File "C:\Users\administrator\AppData\Local\Programs\Python\Python311\Lib\site-packages\django\views\generic\base.py", line 143, in dispatch
    return handler(request, *args, **kwargs)
           ^^^^^^^^^^^^^^^^^^^^^^^^^^^^^^^^^
  File "C:\Users\administrator\Documents\NTTCS_Control_Framework\NTTCS_CF_project\homepage\views.py", line 1122, in post
    c = Evidencias.objects.filter(assessment=consulta)
        ^^^^^^^^^^^^^^^^^^^^^^^^^^^^^^^^^^^^^^^^^^^^^^
  File "C:\Users\administrator\AppData\Local\Programs\Python\Python311\Lib\site-packages\django\db\models\manager.py", line 87, in manager_method
    return getattr(self.get_queryset(), name)(*args, **kwargs)
           ^^^^^^^^^^^^^^^^^^^^^^^^^^^^^^^^^^^^^^^^^^^^^^^^^^^
  File "C:\Users\administrator\AppData\Local\Programs\Python\Python311\Lib\site-packages\django\db\models\query.py", line 1436, in filter
    return self._filter_or_exclude(False, args, kwargs)
           ^^^^^^^^^^^^^^^^^^^^^^^^^^^^^^^^^^^^^^^^^^^^
  File "C:\Users\administrator\AppData\Local\Programs\Python\Python311\Lib\site-packages\django\db\models\query.py", line 1454, in _filter_or_exclude
    clone._filter_or_exclude_inplace(negate, args, kwargs)
  File "C:\Users\administrator\AppData\Local\Programs\Python\Python311\Lib\site-packages\django\db\models\query.py", line 1461, in _filter_or_exclude_inplace
    self._query.add_q(Q(*args, **kwargs))
  File "C:\Users\administrator\AppData\Local\Programs\Python\Python311\Lib\site-packages\django\db\models\sql\query.py", line 1534, in add_q
    clause, _ = self._add_q(q_object, self.used_aliases)
                ^^^^^^^^^^^^^^^^^^^^^^^^^^^^^^^^^^^^^^^^
  File "C:\Users\administrator\AppData\Local\Programs\Python\Python311\Lib\site-packages\django\db\models\sql\query.py", line 1565, in _add_q
    child_clause, needed_inner = self.build_filter(
                                 ^^^^^^^^^^^^^^^^^^
  File "C:\Users\administrator\AppData\Local\Programs\Python\Python311\Lib\site-packages\django\db\models\sql\query.py", line 1480, in build_filter
    condition = self.build_lookup(lookups, col, value)
                ^^^^^^^^^^^^^^^^^^^^^^^^^^^^^^^^^^^^^^
  File "C:\Users\administrator\AppData\Local\Programs\Python\Python311\Lib\site-packages\django\db\models\sql\query.py", line 1307, in build_lookup
    lookup = lookup_class(lhs, rhs)
             ^^^^^^^^^^^^^^^^^^^^^^
  File "C:\Users\administrator\AppData\Local\Programs\Python\Python311\Lib\site-packages\django\db\models\lookups.py", line 27, in __init__
    self.rhs = self.get_prep_lookup()
               ^^^^^^^^^^^^^^^^^^^^^^
  File "C:\Users\administrator\AppData\Local\Programs\Python\Python311\Lib\site-packages\django\db\models\fields\related_lookups.py", line 168, in get_prep_lookup
    return super().get_prep_lookup()
           ^^^^^^^^^^^^^^^^^^^^^^^^^
  File "C:\Users\administrator\AppData\Local\Programs\Python\Python311\Lib\site-packages\django\db\models\lookups.py", line 337, in get_prep_lookup
    raise ValueError(
ValueError: The QuerySet value for an exact lookup must be limited to one result using slicing.
[20/Jul/2023 10:04:01] "POST /MantenimientoAssessmentArchivados/ HTTP/1.1" 500 132394
[20/Jul/2023 10:04:42] "POST /assessment/ HTTP/1.1" 200 57545
[20/Jul/2023 10:04:47] "POST /assessment/ HTTP/1.1" 200 57570
[20/Jul/2023 10:04:53] "POST /assessment/ HTTP/1.1" 200 57545
[20/Jul/2023 10:05:00] "POST /assessment/ HTTP/1.1" 200 57545
[20/Jul/2023 10:05:07] "POST /assessment/ HTTP/1.1" 200 57570
[20/Jul/2023 10:05:19] "POST /assessment/ HTTP/1.1" 200 57545
[20/Jul/2023 10:05:24] "GET /assessmentselect/ HTTP/1.1" 200 21248
[20/Jul/2023 10:05:24] "GET /staticfiles/css/estilos.css HTTP/1.1" 304 0
[20/Jul/2023 10:05:25] "POST /assessment/ HTTP/1.1" 200 57570
[20/Jul/2023 10:05:44] "POST /assessmentselect/ HTTP/1.1" 302 0
Internal Server Error: /assessment/
Traceback (most recent call last):
  File "C:\Users\administrator\AppData\Local\Programs\Python\Python311\Lib\site-packages\mysql\connector\connection_cext.py", line 416, in get_rows
    row = fetch_row()
          ^^^^^^^^^^^
_mysql_connector.MySQLInterfaceError: Table definition has changed, please retry transaction

The above exception was the direct cause of the following exception:

Traceback (most recent call last):
  File "C:\Users\administrator\AppData\Local\Programs\Python\Python311\Lib\site-packages\django\core\handlers\exception.py", line 55, in inner
    response = get_response(request)
               ^^^^^^^^^^^^^^^^^^^^^
  File "C:\Users\administrator\AppData\Local\Programs\Python\Python311\Lib\site-packages\django\core\handlers\base.py", line 197, in _get_response
    response = wrapped_callback(request, *callback_args, **callback_kwargs)
               ^^^^^^^^^^^^^^^^^^^^^^^^^^^^^^^^^^^^^^^^^^^^^^^^^^^^^^^^^^^^
  File "C:\Users\administrator\AppData\Local\Programs\Python\Python311\Lib\site-packages\django\views\generic\base.py", line 104, in view
    return self.dispatch(request, *args, **kwargs)
           ^^^^^^^^^^^^^^^^^^^^^^^^^^^^^^^^^^^^^^^
  File "C:\Users\administrator\AppData\Local\Programs\Python\Python311\Lib\site-packages\django\contrib\auth\mixins.py", line 73, in dispatch
    return super().dispatch(request, *args, **kwargs)
           ^^^^^^^^^^^^^^^^^^^^^^^^^^^^^^^^^^^^^^^^^^
  File "C:\Users\administrator\AppData\Local\Programs\Python\Python311\Lib\site-packages\django\views\generic\base.py", line 143, in dispatch
    return handler(request, *args, **kwargs)
           ^^^^^^^^^^^^^^^^^^^^^^^^^^^^^^^^^
  File "C:\Users\administrator\AppData\Local\Programs\Python\Python311\Lib\site-packages\django\views\generic\base.py", line 226, in get
    context = self.get_context_data(**kwargs)
              ^^^^^^^^^^^^^^^^^^^^^^^^^^^^^^^
  File "C:\Users\administrator\Documents\NTTCS_Control_Framework\NTTCS_CF_project\homepage\views.py", line 280, in get_context_data
    mycursor.execute("SELECT * FROM " + assSelect)
  File "C:\Users\administrator\AppData\Local\Programs\Python\Python311\Lib\site-packages\mysql\connector\cursor_cext.py", line 342, in execute
    self._handle_result(result)
  File "C:\Users\administrator\AppData\Local\Programs\Python\Python311\Lib\site-packages\mysql\connector\cursor_cext.py", line 230, in _handle_result
    self._handle_resultset()
  File "C:\Users\administrator\AppData\Local\Programs\Python\Python311\Lib\site-packages\mysql\connector\cursor_cext.py", line 788, in _handle_resultset
    self._rows = self._cnx.get_rows()[0]
                 ^^^^^^^^^^^^^^^^^^^^
  File "C:\Users\administrator\AppData\Local\Programs\Python\Python311\Lib\site-packages\mysql\connector\connection_cext.py", line 445, in get_rows
    raise get_mysql_exception(
mysql.connector.errors.DatabaseError: 1412 (HY000): Table definition has changed, please retry transaction
[20/Jul/2023 10:05:44] "GET /assessment/ HTTP/1.1" 500 105289
[20/Jul/2023 10:05:49] "POST /assessment/ HTTP/1.1" 200 51509
Internal Server Error: /assessment/
Traceback (most recent call last):
  File "C:\Users\administrator\Documents\NTTCS_Control_Framework\NTTCS_CF_project\homepage\views.py", line 263, in contextTotal
    c = Evidencerequestcatalog.objects.get(evidence_request_references=i)
        ^^^^^^^^^^^^^^^^^^^^^^^^^^^^^^^^^^^^^^^^^^^^^^^^^^^^^^^^^^^^^^^^^
  File "C:\Users\administrator\AppData\Local\Programs\Python\Python311\Lib\site-packages\django\db\models\manager.py", line 87, in manager_method
    return getattr(self.get_queryset(), name)(*args, **kwargs)
           ^^^^^^^^^^^^^^^^^^^^^^^^^^^^^^^^^^^^^^^^^^^^^^^^^^^
  File "C:\Users\administrator\AppData\Local\Programs\Python\Python311\Lib\site-packages\django\db\models\query.py", line 637, in get
    raise self.model.DoesNotExist(
homepage.models.Evidencerequestcatalog.DoesNotExist: Evidencerequestcatalog matching query does not exist.

During handling of the above exception, another exception occurred:

Traceback (most recent call last):
  File "C:\Users\administrator\AppData\Local\Programs\Python\Python311\Lib\site-packages\django\core\handlers\exception.py", line 55, in inner
    response = get_response(request)
               ^^^^^^^^^^^^^^^^^^^^^
  File "C:\Users\administrator\AppData\Local\Programs\Python\Python311\Lib\site-packages\django\core\handlers\base.py", line 197, in _get_response
    response = wrapped_callback(request, *callback_args, **callback_kwargs)
               ^^^^^^^^^^^^^^^^^^^^^^^^^^^^^^^^^^^^^^^^^^^^^^^^^^^^^^^^^^^^
  File "C:\Users\administrator\AppData\Local\Programs\Python\Python311\Lib\site-packages\django\views\generic\base.py", line 104, in view
    return self.dispatch(request, *args, **kwargs)
           ^^^^^^^^^^^^^^^^^^^^^^^^^^^^^^^^^^^^^^^
  File "C:\Users\administrator\AppData\Local\Programs\Python\Python311\Lib\site-packages\django\contrib\auth\mixins.py", line 73, in dispatch
    return super().dispatch(request, *args, **kwargs)
           ^^^^^^^^^^^^^^^^^^^^^^^^^^^^^^^^^^^^^^^^^^
  File "C:\Users\administrator\AppData\Local\Programs\Python\Python311\Lib\site-packages\django\views\generic\base.py", line 143, in dispatch
    return handler(request, *args, **kwargs)
           ^^^^^^^^^^^^^^^^^^^^^^^^^^^^^^^^^
  File "C:\Users\administrator\Documents\NTTCS_Control_Framework\NTTCS_CF_project\homepage\views.py", line 364, in post
    request, context = self.contextTotal(request, controlId, assSelect, context)
                       ^^^^^^^^^^^^^^^^^^^^^^^^^^^^^^^^^^^^^^^^^^^^^^^^^^^^^^^^^
  File "C:\Users\administrator\Documents\NTTCS_Control_Framework\NTTCS_CF_project\homepage\views.py", line 266, in contextTotal
    c = Evidencias.objects.get(evidencia_id=i)
        ^^^^^^^^^^^^^^^^^^^^^^^^^^^^^^^^^^^^^^
  File "C:\Users\administrator\AppData\Local\Programs\Python\Python311\Lib\site-packages\django\db\models\manager.py", line 87, in manager_method
    return getattr(self.get_queryset(), name)(*args, **kwargs)
           ^^^^^^^^^^^^^^^^^^^^^^^^^^^^^^^^^^^^^^^^^^^^^^^^^^^
  File "C:\Users\administrator\AppData\Local\Programs\Python\Python311\Lib\site-packages\django\db\models\query.py", line 637, in get
    raise self.model.DoesNotExist(
homepage.models.Evidencias.DoesNotExist: Evidencias matching query does not exist.
[20/Jul/2023 10:06:47] "POST /assessment/ HTTP/1.1" 500 141654
Internal Server Error: /assessment/
Traceback (most recent call last):
  File "C:\Users\administrator\Documents\NTTCS_Control_Framework\NTTCS_CF_project\homepage\views.py", line 263, in contextTotal
    c = Evidencerequestcatalog.objects.get(evidence_request_references=i)
        ^^^^^^^^^^^^^^^^^^^^^^^^^^^^^^^^^^^^^^^^^^^^^^^^^^^^^^^^^^^^^^^^^
  File "C:\Users\administrator\AppData\Local\Programs\Python\Python311\Lib\site-packages\django\db\models\manager.py", line 87, in manager_method
    return getattr(self.get_queryset(), name)(*args, **kwargs)
           ^^^^^^^^^^^^^^^^^^^^^^^^^^^^^^^^^^^^^^^^^^^^^^^^^^^
  File "C:\Users\administrator\AppData\Local\Programs\Python\Python311\Lib\site-packages\django\db\models\query.py", line 637, in get
    raise self.model.DoesNotExist(
homepage.models.Evidencerequestcatalog.DoesNotExist: Evidencerequestcatalog matching query does not exist.

During handling of the above exception, another exception occurred:

Traceback (most recent call last):
  File "C:\Users\administrator\AppData\Local\Programs\Python\Python311\Lib\site-packages\django\core\handlers\exception.py", line 55, in inner
    response = get_response(request)
               ^^^^^^^^^^^^^^^^^^^^^
  File "C:\Users\administrator\AppData\Local\Programs\Python\Python311\Lib\site-packages\django\core\handlers\base.py", line 197, in _get_response
    response = wrapped_callback(request, *callback_args, **callback_kwargs)
               ^^^^^^^^^^^^^^^^^^^^^^^^^^^^^^^^^^^^^^^^^^^^^^^^^^^^^^^^^^^^
  File "C:\Users\administrator\AppData\Local\Programs\Python\Python311\Lib\site-packages\django\views\generic\base.py", line 104, in view
    return self.dispatch(request, *args, **kwargs)
           ^^^^^^^^^^^^^^^^^^^^^^^^^^^^^^^^^^^^^^^
  File "C:\Users\administrator\AppData\Local\Programs\Python\Python311\Lib\site-packages\django\contrib\auth\mixins.py", line 73, in dispatch
    return super().dispatch(request, *args, **kwargs)
           ^^^^^^^^^^^^^^^^^^^^^^^^^^^^^^^^^^^^^^^^^^
  File "C:\Users\administrator\AppData\Local\Programs\Python\Python311\Lib\site-packages\django\views\generic\base.py", line 143, in dispatch
    return handler(request, *args, **kwargs)
           ^^^^^^^^^^^^^^^^^^^^^^^^^^^^^^^^^
  File "C:\Users\administrator\Documents\NTTCS_Control_Framework\NTTCS_CF_project\homepage\views.py", line 364, in post
    request, context = self.contextTotal(request, controlId, assSelect, context)
                       ^^^^^^^^^^^^^^^^^^^^^^^^^^^^^^^^^^^^^^^^^^^^^^^^^^^^^^^^^
  File "C:\Users\administrator\Documents\NTTCS_Control_Framework\NTTCS_CF_project\homepage\views.py", line 266, in contextTotal
    c = Evidencias.objects.get(evidencia_id=i)
        ^^^^^^^^^^^^^^^^^^^^^^^^^^^^^^^^^^^^^^
  File "C:\Users\administrator\AppData\Local\Programs\Python\Python311\Lib\site-packages\django\db\models\manager.py", line 87, in manager_method
    return getattr(self.get_queryset(), name)(*args, **kwargs)
           ^^^^^^^^^^^^^^^^^^^^^^^^^^^^^^^^^^^^^^^^^^^^^^^^^^^
  File "C:\Users\administrator\AppData\Local\Programs\Python\Python311\Lib\site-packages\django\db\models\query.py", line 637, in get
    raise self.model.DoesNotExist(
homepage.models.Evidencias.DoesNotExist: Evidencias matching query does not exist.
[20/Jul/2023 10:08:35] "POST /assessment/ HTTP/1.1" 500 141833
Internal Server Error: /assessment/
Traceback (most recent call last):
  File "C:\Users\administrator\Documents\NTTCS_Control_Framework\NTTCS_CF_project\homepage\views.py", line 263, in contextTotal
    c = Evidencerequestcatalog.objects.get(evidence_request_references=i)
        ^^^^^^^^^^^^^^^^^^^^^^^^^^^^^^^^^^^^^^^^^^^^^^^^^^^^^^^^^^^^^^^^^
  File "C:\Users\administrator\AppData\Local\Programs\Python\Python311\Lib\site-packages\django\db\models\manager.py", line 87, in manager_method
    return getattr(self.get_queryset(), name)(*args, **kwargs)
           ^^^^^^^^^^^^^^^^^^^^^^^^^^^^^^^^^^^^^^^^^^^^^^^^^^^
  File "C:\Users\administrator\AppData\Local\Programs\Python\Python311\Lib\site-packages\django\db\models\query.py", line 637, in get
    raise self.model.DoesNotExist(
homepage.models.Evidencerequestcatalog.DoesNotExist: Evidencerequestcatalog matching query does not exist.

During handling of the above exception, another exception occurred:

Traceback (most recent call last):
  File "C:\Users\administrator\AppData\Local\Programs\Python\Python311\Lib\site-packages\django\core\handlers\exception.py", line 55, in inner
    response = get_response(request)
               ^^^^^^^^^^^^^^^^^^^^^
  File "C:\Users\administrator\AppData\Local\Programs\Python\Python311\Lib\site-packages\django\core\handlers\base.py", line 197, in _get_response
    response = wrapped_callback(request, *callback_args, **callback_kwargs)
               ^^^^^^^^^^^^^^^^^^^^^^^^^^^^^^^^^^^^^^^^^^^^^^^^^^^^^^^^^^^^
  File "C:\Users\administrator\AppData\Local\Programs\Python\Python311\Lib\site-packages\django\views\generic\base.py", line 104, in view
    return self.dispatch(request, *args, **kwargs)
           ^^^^^^^^^^^^^^^^^^^^^^^^^^^^^^^^^^^^^^^
  File "C:\Users\administrator\AppData\Local\Programs\Python\Python311\Lib\site-packages\django\contrib\auth\mixins.py", line 73, in dispatch
    return super().dispatch(request, *args, **kwargs)
           ^^^^^^^^^^^^^^^^^^^^^^^^^^^^^^^^^^^^^^^^^^
  File "C:\Users\administrator\AppData\Local\Programs\Python\Python311\Lib\site-packages\django\views\generic\base.py", line 143, in dispatch
    return handler(request, *args, **kwargs)
           ^^^^^^^^^^^^^^^^^^^^^^^^^^^^^^^^^
  File "C:\Users\administrator\Documents\NTTCS_Control_Framework\NTTCS_CF_project\homepage\views.py", line 368, in post
    request, context = self.contextTotal(request, controlId, assSelect, context)
                       ^^^^^^^^^^^^^^^^^^^^^^^^^^^^^^^^^^^^^^^^^^^^^^^^^^^^^^^^^
  File "C:\Users\administrator\Documents\NTTCS_Control_Framework\NTTCS_CF_project\homepage\views.py", line 266, in contextTotal
    c = Evidencias.objects.get(evidencia_id=i)
        ^^^^^^^^^^^^^^^^^^^^^^^^^^^^^^^^^^^^^^
  File "C:\Users\administrator\AppData\Local\Programs\Python\Python311\Lib\site-packages\django\db\models\manager.py", line 87, in manager_method
    return getattr(self.get_queryset(), name)(*args, **kwargs)
           ^^^^^^^^^^^^^^^^^^^^^^^^^^^^^^^^^^^^^^^^^^^^^^^^^^^
  File "C:\Users\administrator\AppData\Local\Programs\Python\Python311\Lib\site-packages\django\db\models\query.py", line 637, in get
    raise self.model.DoesNotExist(
homepage.models.Evidencias.DoesNotExist: Evidencias matching query does not exist.
[20/Jul/2023 10:08:44] "POST /assessment/ HTTP/1.1" 500 135169
[20/Jul/2023 10:09:04] "POST /assessment/ HTTP/1.1" 200 57547
[20/Jul/2023 10:09:12] "POST /assessment/ HTTP/1.1" 200 57572
[20/Jul/2023 10:11:09] "POST /assessment/ HTTP/1.1" 200 57547
[20/Jul/2023 10:11:18] "POST /assessment/ HTTP/1.1" 200 51806
[20/Jul/2023 10:11:24] "POST /assessment/ HTTP/1.1" 200 57572
[20/Jul/2023 10:11:32] "POST /assessment/ HTTP/1.1" 200 57547
[20/Jul/2023 10:13:46] "POST /assessment/ HTTP/1.1" 200 52566
[20/Jul/2023 10:15:27] "POST /assessment/ HTTP/1.1" 200 52662
[20/Jul/2023 10:15:50] "POST /assessment/ HTTP/1.1" 200 59011
[20/Jul/2023 10:16:07] "POST /assessment/ HTTP/1.1" 200 59140
[20/Jul/2023 10:16:11] "POST /assessment/ HTTP/1.1" 200 59140
[20/Jul/2023 10:19:13] "POST /assessment/ HTTP/1.1" 200 57559
[20/Jul/2023 10:19:25] "POST /assessment/ HTTP/1.1" 200 57534
[20/Jul/2023 10:19:33] "POST /assessment/ HTTP/1.1" 200 57559
[20/Jul/2023 10:19:37] "POST /assessment/ HTTP/1.1" 200 57534
[20/Jul/2023 10:19:42] "POST /assessment/ HTTP/1.1" 200 51340
[20/Jul/2023 10:19:44] "POST /assessment/ HTTP/1.1" 200 51806
C:\Users\administrator\Documents\NTTCS_Control_Framework\NTTCS_CF_project\homepage\views.py changed, reloading.
Performing system checks...

System check identified no issues (0 silenced).
July 20, 2023 - 09:44:18
Django version 4.2.2, using settings 'NTTCS_CF_project.settings'
Starting development server at http://127.0.0.1:9242/
Quit the server with CTRL-BREAK.

pbkdf2_sha256$600000$hihZxii43CmRYYgrZS6d1A$uUT74EWzIPwlHj6n+CRV5CtPPBpyuRSWhk8nheoWf/0=
NTT-AST-01
NTT-AST-01
NTT-AST-01
NTT-AST-02
NTT-AST-02.3
NTT-AST-02.3
NTT-AST-02.3
NTT-AST-02.6
NTT-BCD-11
Watching for file changes with StatReloader
Exception in thread django-main-thread:
Traceback (most recent call last):
  File "C:\Users\administrator\AppData\Local\Programs\Python\Python311\Lib\threading.py", line 1038, in _bootstrap_inner
    self.run()
  File "C:\Users\administrator\AppData\Local\Programs\Python\Python311\Lib\threading.py", line 975, in run
    self._target(*self._args, **self._kwargs)
  File "C:\Users\administrator\AppData\Local\Programs\Python\Python311\Lib\site-packages\django\utils\autoreload.py", line 64, in wrapper
    fn(*args, **kwargs)
  File "C:\Users\administrator\AppData\Local\Programs\Python\Python311\Lib\site-packages\django\core\management\commands\runserver.py", line 133, in inner_run
    self.check(display_num_errors=True)
  File "C:\Users\administrator\AppData\Local\Programs\Python\Python311\Lib\site-packages\django\core\management\base.py", line 485, in check
    all_issues = checks.run_checks(
                 ^^^^^^^^^^^^^^^^^^
  File "C:\Users\administrator\AppData\Local\Programs\Python\Python311\Lib\site-packages\django\core\checks\registry.py", line 88, in run_checks
    new_errors = check(app_configs=app_configs, databases=databases)
                 ^^^^^^^^^^^^^^^^^^^^^^^^^^^^^^^^^^^^^^^^^^^^^^^^^^^
  File "C:\Users\administrator\AppData\Local\Programs\Python\Python311\Lib\site-packages\django\core\checks\urls.py", line 42, in check_url_namespaces_unique
    all_namespaces = _load_all_namespaces(resolver)
                     ^^^^^^^^^^^^^^^^^^^^^^^^^^^^^^
  File "C:\Users\administrator\AppData\Local\Programs\Python\Python311\Lib\site-packages\django\core\checks\urls.py", line 61, in _load_all_namespaces
    url_patterns = getattr(resolver, "url_patterns", [])
                   ^^^^^^^^^^^^^^^^^^^^^^^^^^^^^^^^^^^^^
  File "C:\Users\administrator\AppData\Local\Programs\Python\Python311\Lib\site-packages\django\utils\functional.py", line 57, in __get__
    res = instance.__dict__[self.name] = self.func(instance)
                                         ^^^^^^^^^^^^^^^^^^^
  File "C:\Users\administrator\AppData\Local\Programs\Python\Python311\Lib\site-packages\django\urls\resolvers.py", line 715, in url_patterns
    patterns = getattr(self.urlconf_module, "urlpatterns", self.urlconf_module)
                       ^^^^^^^^^^^^^^^^^^^
  File "C:\Users\administrator\AppData\Local\Programs\Python\Python311\Lib\site-packages\django\utils\functional.py", line 57, in __get__
    res = instance.__dict__[self.name] = self.func(instance)
                                         ^^^^^^^^^^^^^^^^^^^
  File "C:\Users\administrator\AppData\Local\Programs\Python\Python311\Lib\site-packages\django\urls\resolvers.py", line 708, in urlconf_module
    return import_module(self.urlconf_name)
           ^^^^^^^^^^^^^^^^^^^^^^^^^^^^^^^^
  File "C:\Users\administrator\AppData\Local\Programs\Python\Python311\Lib\importlib\__init__.py", line 126, in import_module
    return _bootstrap._gcd_import(name[level:], package, level)
           ^^^^^^^^^^^^^^^^^^^^^^^^^^^^^^^^^^^^^^^^^^^^^^^^^^^^
  File "<frozen importlib._bootstrap>", line 1204, in _gcd_import
  File "<frozen importlib._bootstrap>", line 1176, in _find_and_load
  File "<frozen importlib._bootstrap>", line 1147, in _find_and_load_unlocked
  File "<frozen importlib._bootstrap>", line 690, in _load_unlocked
  File "<frozen importlib._bootstrap_external>", line 940, in exec_module
  File "<frozen importlib._bootstrap>", line 241, in _call_with_frames_removed
  File "C:\Users\administrator\Documents\NTTCS_Control_Framework\NTTCS_CF_project\NTTCS_CF_project\urls.py", line 22, in <module>
    path('', include('homepage.urls')),
             ^^^^^^^^^^^^^^^^^^^^^^^^
  File "C:\Users\administrator\AppData\Local\Programs\Python\Python311\Lib\site-packages\django\urls\conf.py", line 38, in include
    urlconf_module = import_module(urlconf_module)
                     ^^^^^^^^^^^^^^^^^^^^^^^^^^^^^
  File "C:\Users\administrator\AppData\Local\Programs\Python\Python311\Lib\importlib\__init__.py", line 126, in import_module
    return _bootstrap._gcd_import(name[level:], package, level)
           ^^^^^^^^^^^^^^^^^^^^^^^^^^^^^^^^^^^^^^^^^^^^^^^^^^^^
  File "<frozen importlib._bootstrap>", line 1204, in _gcd_import
  File "<frozen importlib._bootstrap>", line 1176, in _find_and_load
  File "<frozen importlib._bootstrap>", line 1147, in _find_and_load_unlocked
  File "<frozen importlib._bootstrap>", line 690, in _load_unlocked
  File "<frozen importlib._bootstrap_external>", line 940, in exec_module
  File "<frozen importlib._bootstrap>", line 241, in _call_with_frames_removed
  File "C:\Users\administrator\Documents\NTTCS_Control_Framework\NTTCS_CF_project\homepage\urls.py", line 2, in <module>
    from . import views
  File "C:\Users\administrator\Documents\NTTCS_Control_Framework\NTTCS_CF_project\homepage\views.py", line 265
    except:
    ^^^^^^
SyntaxError: invalid syntax
C:\Users\administrator\Documents\NTTCS_Control_Framework\NTTCS_CF_project\homepage\views.py changed, reloading.
Performing system checks...

Watching for file changes with StatReloader
Exception in thread django-main-thread:
Traceback (most recent call last):
  File "C:\Users\administrator\AppData\Local\Programs\Python\Python311\Lib\threading.py", line 1038, in _bootstrap_inner
    self.run()
  File "C:\Users\administrator\AppData\Local\Programs\Python\Python311\Lib\threading.py", line 975, in run
    self._target(*self._args, **self._kwargs)
  File "C:\Users\administrator\AppData\Local\Programs\Python\Python311\Lib\site-packages\django\utils\autoreload.py", line 64, in wrapper
    fn(*args, **kwargs)
  File "C:\Users\administrator\AppData\Local\Programs\Python\Python311\Lib\site-packages\django\core\management\commands\runserver.py", line 133, in inner_run
    self.check(display_num_errors=True)
  File "C:\Users\administrator\AppData\Local\Programs\Python\Python311\Lib\site-packages\django\core\management\base.py", line 485, in check
    all_issues = checks.run_checks(
                 ^^^^^^^^^^^^^^^^^^
  File "C:\Users\administrator\AppData\Local\Programs\Python\Python311\Lib\site-packages\django\core\checks\registry.py", line 88, in run_checks
    new_errors = check(app_configs=app_configs, databases=databases)
                 ^^^^^^^^^^^^^^^^^^^^^^^^^^^^^^^^^^^^^^^^^^^^^^^^^^^
  File "C:\Users\administrator\AppData\Local\Programs\Python\Python311\Lib\site-packages\django\core\checks\urls.py", line 42, in check_url_namespaces_unique
    all_namespaces = _load_all_namespaces(resolver)
                     ^^^^^^^^^^^^^^^^^^^^^^^^^^^^^^
  File "C:\Users\administrator\AppData\Local\Programs\Python\Python311\Lib\site-packages\django\core\checks\urls.py", line 61, in _load_all_namespaces
    url_patterns = getattr(resolver, "url_patterns", [])
                   ^^^^^^^^^^^^^^^^^^^^^^^^^^^^^^^^^^^^^
  File "C:\Users\administrator\AppData\Local\Programs\Python\Python311\Lib\site-packages\django\utils\functional.py", line 57, in __get__
    res = instance.__dict__[self.name] = self.func(instance)
                                         ^^^^^^^^^^^^^^^^^^^
  File "C:\Users\administrator\AppData\Local\Programs\Python\Python311\Lib\site-packages\django\urls\resolvers.py", line 715, in url_patterns
    patterns = getattr(self.urlconf_module, "urlpatterns", self.urlconf_module)
                       ^^^^^^^^^^^^^^^^^^^
  File "C:\Users\administrator\AppData\Local\Programs\Python\Python311\Lib\site-packages\django\utils\functional.py", line 57, in __get__
    res = instance.__dict__[self.name] = self.func(instance)
                                         ^^^^^^^^^^^^^^^^^^^
  File "C:\Users\administrator\AppData\Local\Programs\Python\Python311\Lib\site-packages\django\urls\resolvers.py", line 708, in urlconf_module
    return import_module(self.urlconf_name)
           ^^^^^^^^^^^^^^^^^^^^^^^^^^^^^^^^
  File "C:\Users\administrator\AppData\Local\Programs\Python\Python311\Lib\importlib\__init__.py", line 126, in import_module
    return _bootstrap._gcd_import(name[level:], package, level)
           ^^^^^^^^^^^^^^^^^^^^^^^^^^^^^^^^^^^^^^^^^^^^^^^^^^^^
  File "<frozen importlib._bootstrap>", line 1204, in _gcd_import
  File "<frozen importlib._bootstrap>", line 1176, in _find_and_load
  File "<frozen importlib._bootstrap>", line 1147, in _find_and_load_unlocked
  File "<frozen importlib._bootstrap>", line 690, in _load_unlocked
  File "<frozen importlib._bootstrap_external>", line 940, in exec_module
  File "<frozen importlib._bootstrap>", line 241, in _call_with_frames_removed
  File "C:\Users\administrator\Documents\NTTCS_Control_Framework\NTTCS_CF_project\NTTCS_CF_project\urls.py", line 22, in <module>
    path('', include('homepage.urls')),
             ^^^^^^^^^^^^^^^^^^^^^^^^
  File "C:\Users\administrator\AppData\Local\Programs\Python\Python311\Lib\site-packages\django\urls\conf.py", line 38, in include
    urlconf_module = import_module(urlconf_module)
                     ^^^^^^^^^^^^^^^^^^^^^^^^^^^^^
  File "C:\Users\administrator\AppData\Local\Programs\Python\Python311\Lib\importlib\__init__.py", line 126, in import_module
    return _bootstrap._gcd_import(name[level:], package, level)
           ^^^^^^^^^^^^^^^^^^^^^^^^^^^^^^^^^^^^^^^^^^^^^^^^^^^^
  File "<frozen importlib._bootstrap>", line 1204, in _gcd_import
  File "<frozen importlib._bootstrap>", line 1176, in _find_and_load
  File "<frozen importlib._bootstrap>", line 1147, in _find_and_load_unlocked
  File "<frozen importlib._bootstrap>", line 690, in _load_unlocked
  File "<frozen importlib._bootstrap_external>", line 940, in exec_module
  File "<frozen importlib._bootstrap>", line 241, in _call_with_frames_removed
  File "C:\Users\administrator\Documents\NTTCS_Control_Framework\NTTCS_CF_project\homepage\urls.py", line 2, in <module>
    from . import views
  File "C:\Users\administrator\Documents\NTTCS_Control_Framework\NTTCS_CF_project\homepage\views.py", line 265
    except:
    ^^^^^^
SyntaxError: invalid syntax
C:\Users\administrator\Documents\NTTCS_Control_Framework\NTTCS_CF_project\homepage\views.py changed, reloading.
Performing system checks...

Watching for file changes with StatReloader
Internal Server Error: /assessment/
Traceback (most recent call last):
  File "C:\Users\administrator\AppData\Local\Programs\Python\Python311\Lib\site-packages\django\core\handlers\exception.py", line 55, in inner
    response = get_response(request)
               ^^^^^^^^^^^^^^^^^^^^^
  File "C:\Users\administrator\AppData\Local\Programs\Python\Python311\Lib\site-packages\django\core\handlers\base.py", line 197, in _get_response
    response = wrapped_callback(request, *callback_args, **callback_kwargs)
               ^^^^^^^^^^^^^^^^^^^^^^^^^^^^^^^^^^^^^^^^^^^^^^^^^^^^^^^^^^^^
  File "C:\Users\administrator\AppData\Local\Programs\Python\Python311\Lib\site-packages\django\views\generic\base.py", line 104, in view
    return self.dispatch(request, *args, **kwargs)
           ^^^^^^^^^^^^^^^^^^^^^^^^^^^^^^^^^^^^^^^
  File "C:\Users\administrator\AppData\Local\Programs\Python\Python311\Lib\site-packages\django\contrib\auth\mixins.py", line 73, in dispatch
    return super().dispatch(request, *args, **kwargs)
           ^^^^^^^^^^^^^^^^^^^^^^^^^^^^^^^^^^^^^^^^^^
  File "C:\Users\administrator\AppData\Local\Programs\Python\Python311\Lib\site-packages\django\views\generic\base.py", line 143, in dispatch
    return handler(request, *args, **kwargs)
           ^^^^^^^^^^^^^^^^^^^^^^^^^^^^^^^^^
  File "C:\Users\administrator\Documents\NTTCS_Control_Framework\NTTCS_CF_project\homepage\views.py", line 364, in post
    request, context = self.contextTotal(request, controlId, assSelect, context)
                       ^^^^^^^^^^^^^^^^^^^^^^^^^^^^^^^^^^^^^^^^^^^^^^^^^^^^^^^^^
  File "C:\Users\administrator\Documents\NTTCS_Control_Framework\NTTCS_CF_project\homepage\views.py", line 266, in contextTotal
    c = Evidencias.objects.get(evidencia_id=i)
        ^^^^^^^^^^^^^^^^^^^^^^^^^^^^^^^^^^^^^^
  File "C:\Users\administrator\AppData\Local\Programs\Python\Python311\Lib\site-packages\django\db\models\manager.py", line 87, in manager_method
    return getattr(self.get_queryset(), name)(*args, **kwargs)
           ^^^^^^^^^^^^^^^^^^^^^^^^^^^^^^^^^^^^^^^^^^^^^^^^^^^
  File "C:\Users\administrator\AppData\Local\Programs\Python\Python311\Lib\site-packages\django\db\models\query.py", line 637, in get
    raise self.model.DoesNotExist(
homepage.models.Evidencias.DoesNotExist: Evidencias matching query does not exist.
[20/Jul/2023 10:22:03] "POST /assessment/ HTTP/1.1" 500 115913
Internal Server Error: /assessment/
Traceback (most recent call last):
  File "C:\Users\administrator\AppData\Local\Programs\Python\Python311\Lib\site-packages\django\core\handlers\exception.py", line 55, in inner
    response = get_response(request)
               ^^^^^^^^^^^^^^^^^^^^^
  File "C:\Users\administrator\AppData\Local\Programs\Python\Python311\Lib\site-packages\django\core\handlers\base.py", line 197, in _get_response
    response = wrapped_callback(request, *callback_args, **callback_kwargs)
               ^^^^^^^^^^^^^^^^^^^^^^^^^^^^^^^^^^^^^^^^^^^^^^^^^^^^^^^^^^^^
  File "C:\Users\administrator\AppData\Local\Programs\Python\Python311\Lib\site-packages\django\views\generic\base.py", line 104, in view
    return self.dispatch(request, *args, **kwargs)
           ^^^^^^^^^^^^^^^^^^^^^^^^^^^^^^^^^^^^^^^
  File "C:\Users\administrator\AppData\Local\Programs\Python\Python311\Lib\site-packages\django\contrib\auth\mixins.py", line 73, in dispatch
    return super().dispatch(request, *args, **kwargs)
           ^^^^^^^^^^^^^^^^^^^^^^^^^^^^^^^^^^^^^^^^^^
  File "C:\Users\administrator\AppData\Local\Programs\Python\Python311\Lib\site-packages\django\views\generic\base.py", line 143, in dispatch
    return handler(request, *args, **kwargs)
           ^^^^^^^^^^^^^^^^^^^^^^^^^^^^^^^^^
  File "C:\Users\administrator\Documents\NTTCS_Control_Framework\NTTCS_CF_project\homepage\views.py", line 368, in post
    request, context = self.contextTotal(request, controlId, assSelect, context)
                       ^^^^^^^^^^^^^^^^^^^^^^^^^^^^^^^^^^^^^^^^^^^^^^^^^^^^^^^^^
  File "C:\Users\administrator\Documents\NTTCS_Control_Framework\NTTCS_CF_project\homepage\views.py", line 266, in contextTotal
    c = Evidencias.objects.get(evidencia_id=i)
        ^^^^^^^^^^^^^^^^^^^^^^^^^^^^^^^^^^^^^^
  File "C:\Users\administrator\AppData\Local\Programs\Python\Python311\Lib\site-packages\django\db\models\manager.py", line 87, in manager_method
    return getattr(self.get_queryset(), name)(*args, **kwargs)
           ^^^^^^^^^^^^^^^^^^^^^^^^^^^^^^^^^^^^^^^^^^^^^^^^^^^
  File "C:\Users\administrator\AppData\Local\Programs\Python\Python311\Lib\site-packages\django\db\models\query.py", line 637, in get
    raise self.model.DoesNotExist(
homepage.models.Evidencias.DoesNotExist: Evidencias matching query does not exist.
[20/Jul/2023 10:22:23] "POST /assessment/ HTTP/1.1" 500 109119
C:\Users\administrator\Documents\NTTCS_Control_Framework\NTTCS_CF_project\homepage\views.py changed, reloading.
Performing system checks...

System check identified no issues (0 silenced).
July 20, 2023 - 10:21:57
Django version 4.2.2, using settings 'NTTCS_CF_project.settings'
Starting development server at http://127.0.0.1:9242/
Quit the server with CTRL-BREAK.

NTT-AST-02.5
NTT-AST-02.5
Watching for file changes with StatReloader
Internal Server Error: /assessment/
Traceback (most recent call last):
  File "C:\Users\administrator\AppData\Local\Programs\Python\Python311\Lib\site-packages\django\core\handlers\exception.py", line 55, in inner
    response = get_response(request)
               ^^^^^^^^^^^^^^^^^^^^^
  File "C:\Users\administrator\AppData\Local\Programs\Python\Python311\Lib\site-packages\django\core\handlers\base.py", line 197, in _get_response
    response = wrapped_callback(request, *callback_args, **callback_kwargs)
               ^^^^^^^^^^^^^^^^^^^^^^^^^^^^^^^^^^^^^^^^^^^^^^^^^^^^^^^^^^^^
  File "C:\Users\administrator\AppData\Local\Programs\Python\Python311\Lib\site-packages\django\views\generic\base.py", line 104, in view
    return self.dispatch(request, *args, **kwargs)
           ^^^^^^^^^^^^^^^^^^^^^^^^^^^^^^^^^^^^^^^
  File "C:\Users\administrator\AppData\Local\Programs\Python\Python311\Lib\site-packages\django\contrib\auth\mixins.py", line 73, in dispatch
    return super().dispatch(request, *args, **kwargs)
           ^^^^^^^^^^^^^^^^^^^^^^^^^^^^^^^^^^^^^^^^^^
  File "C:\Users\administrator\AppData\Local\Programs\Python\Python311\Lib\site-packages\django\views\generic\base.py", line 143, in dispatch
    return handler(request, *args, **kwargs)
           ^^^^^^^^^^^^^^^^^^^^^^^^^^^^^^^^^
  File "C:\Users\administrator\Documents\NTTCS_Control_Framework\NTTCS_CF_project\homepage\views.py", line 368, in post
    request, context = self.contextTotal(request, controlId, assSelect, context)
                       ^^^^^^^^^^^^^^^^^^^^^^^^^^^^^^^^^^^^^^^^^^^^^^^^^^^^^^^^^
  File "C:\Users\administrator\Documents\NTTCS_Control_Framework\NTTCS_CF_project\homepage\views.py", line 266, in contextTotal
    c = Evidencias.objects.get(evidencia_id=i)
        ^^^^^^^^^^^^^^^^^^^^^^^^^^^^^^^^^^^^^^
  File "C:\Users\administrator\AppData\Local\Programs\Python\Python311\Lib\site-packages\django\db\models\manager.py", line 87, in manager_method
    return getattr(self.get_queryset(), name)(*args, **kwargs)
           ^^^^^^^^^^^^^^^^^^^^^^^^^^^^^^^^^^^^^^^^^^^^^^^^^^^
  File "C:\Users\administrator\AppData\Local\Programs\Python\Python311\Lib\site-packages\django\db\models\query.py", line 637, in get
    raise self.model.DoesNotExist(
homepage.models.Evidencias.DoesNotExist: Evidencias matching query does not exist.
[20/Jul/2023 10:23:37] "POST /assessment/ HTTP/1.1" 500 109130
Internal Server Error: /assessment/
Traceback (most recent call last):
  File "C:\Users\administrator\AppData\Local\Programs\Python\Python311\Lib\site-packages\django\core\handlers\exception.py", line 55, in inner
    response = get_response(request)
               ^^^^^^^^^^^^^^^^^^^^^
  File "C:\Users\administrator\AppData\Local\Programs\Python\Python311\Lib\site-packages\django\core\handlers\base.py", line 197, in _get_response
    response = wrapped_callback(request, *callback_args, **callback_kwargs)
               ^^^^^^^^^^^^^^^^^^^^^^^^^^^^^^^^^^^^^^^^^^^^^^^^^^^^^^^^^^^^
  File "C:\Users\administrator\AppData\Local\Programs\Python\Python311\Lib\site-packages\django\views\generic\base.py", line 104, in view
    return self.dispatch(request, *args, **kwargs)
           ^^^^^^^^^^^^^^^^^^^^^^^^^^^^^^^^^^^^^^^
  File "C:\Users\administrator\AppData\Local\Programs\Python\Python311\Lib\site-packages\django\contrib\auth\mixins.py", line 73, in dispatch
    return super().dispatch(request, *args, **kwargs)
           ^^^^^^^^^^^^^^^^^^^^^^^^^^^^^^^^^^^^^^^^^^
  File "C:\Users\administrator\AppData\Local\Programs\Python\Python311\Lib\site-packages\django\views\generic\base.py", line 143, in dispatch
    return handler(request, *args, **kwargs)
           ^^^^^^^^^^^^^^^^^^^^^^^^^^^^^^^^^
  File "C:\Users\administrator\Documents\NTTCS_Control_Framework\NTTCS_CF_project\homepage\views.py", line 308, in post
    request, context = self.contextTotal(request, select, assSelect, context)
                       ^^^^^^^^^^^^^^^^^^^^^^^^^^^^^^^^^^^^^^^^^^^^^^^^^^^^^^
  File "C:\Users\administrator\Documents\NTTCS_Control_Framework\NTTCS_CF_project\homepage\views.py", line 266, in contextTotal
    c = Evidencias.objects.get(evidencia_id=i)
        ^^^^^^^^^^^^^^^^^^^^^^^^^^^^^^^^^^^^^^
  File "C:\Users\administrator\AppData\Local\Programs\Python\Python311\Lib\site-packages\django\db\models\manager.py", line 87, in manager_method
    return getattr(self.get_queryset(), name)(*args, **kwargs)
           ^^^^^^^^^^^^^^^^^^^^^^^^^^^^^^^^^^^^^^^^^^^^^^^^^^^
  File "C:\Users\administrator\AppData\Local\Programs\Python\Python311\Lib\site-packages\django\db\models\query.py", line 637, in get
    raise self.model.DoesNotExist(
homepage.models.Evidencias.DoesNotExist: Evidencias matching query does not exist.
[20/Jul/2023 10:23:44] "POST /assessment/ HTTP/1.1" 500 107333
[20/Jul/2023 10:23:49] "GET /menu/ HTTP/1.1" 200 9360
[20/Jul/2023 10:23:50] "GET /assessmentselect/ HTTP/1.1" 200 21358
[20/Jul/2023 10:23:53] "POST /assessmentselect/ HTTP/1.1" 302 0
[20/Jul/2023 10:23:53] "GET /assessment/ HTTP/1.1" 200 46824
[20/Jul/2023 10:23:57] "POST /assessment/ HTTP/1.1" 200 57559
Internal Server Error: /assessment/
Traceback (most recent call last):
  File "C:\Users\administrator\AppData\Local\Programs\Python\Python311\Lib\site-packages\django\core\handlers\exception.py", line 55, in inner
    response = get_response(request)
               ^^^^^^^^^^^^^^^^^^^^^
  File "C:\Users\administrator\AppData\Local\Programs\Python\Python311\Lib\site-packages\django\core\handlers\base.py", line 197, in _get_response
    response = wrapped_callback(request, *callback_args, **callback_kwargs)
               ^^^^^^^^^^^^^^^^^^^^^^^^^^^^^^^^^^^^^^^^^^^^^^^^^^^^^^^^^^^^
  File "C:\Users\administrator\AppData\Local\Programs\Python\Python311\Lib\site-packages\django\views\generic\base.py", line 104, in view
    return self.dispatch(request, *args, **kwargs)
           ^^^^^^^^^^^^^^^^^^^^^^^^^^^^^^^^^^^^^^^
  File "C:\Users\administrator\AppData\Local\Programs\Python\Python311\Lib\site-packages\django\contrib\auth\mixins.py", line 73, in dispatch
    return super().dispatch(request, *args, **kwargs)
           ^^^^^^^^^^^^^^^^^^^^^^^^^^^^^^^^^^^^^^^^^^
  File "C:\Users\administrator\AppData\Local\Programs\Python\Python311\Lib\site-packages\django\views\generic\base.py", line 143, in dispatch
    return handler(request, *args, **kwargs)
           ^^^^^^^^^^^^^^^^^^^^^^^^^^^^^^^^^
  File "C:\Users\administrator\Documents\NTTCS_Control_Framework\NTTCS_CF_project\homepage\views.py", line 308, in post
    request, context = self.contextTotal(request, select, assSelect, context)
                       ^^^^^^^^^^^^^^^^^^^^^^^^^^^^^^^^^^^^^^^^^^^^^^^^^^^^^^
  File "C:\Users\administrator\Documents\NTTCS_Control_Framework\NTTCS_CF_project\homepage\views.py", line 266, in contextTotal
    c = Evidencias.objects.get(evidencia_id=i)
        ^^^^^^^^^^^^^^^^^^^^^^^^^^^^^^^^^^^^^^
  File "C:\Users\administrator\AppData\Local\Programs\Python\Python311\Lib\site-packages\django\db\models\manager.py", line 87, in manager_method
    return getattr(self.get_queryset(), name)(*args, **kwargs)
           ^^^^^^^^^^^^^^^^^^^^^^^^^^^^^^^^^^^^^^^^^^^^^^^^^^^
  File "C:\Users\administrator\AppData\Local\Programs\Python\Python311\Lib\site-packages\django\db\models\query.py", line 637, in get
    raise self.model.DoesNotExist(
homepage.models.Evidencias.DoesNotExist: Evidencias matching query does not exist.
[20/Jul/2023 10:24:01] "POST /assessment/ HTTP/1.1" 500 107333
Internal Server Error: /assessment/
Traceback (most recent call last):
  File "C:\Users\administrator\AppData\Local\Programs\Python\Python311\Lib\site-packages\django\core\handlers\exception.py", line 55, in inner
    response = get_response(request)
               ^^^^^^^^^^^^^^^^^^^^^
  File "C:\Users\administrator\AppData\Local\Programs\Python\Python311\Lib\site-packages\django\core\handlers\base.py", line 197, in _get_response
    response = wrapped_callback(request, *callback_args, **callback_kwargs)
               ^^^^^^^^^^^^^^^^^^^^^^^^^^^^^^^^^^^^^^^^^^^^^^^^^^^^^^^^^^^^
  File "C:\Users\administrator\AppData\Local\Programs\Python\Python311\Lib\site-packages\django\views\generic\base.py", line 104, in view
    return self.dispatch(request, *args, **kwargs)
           ^^^^^^^^^^^^^^^^^^^^^^^^^^^^^^^^^^^^^^^
  File "C:\Users\administrator\AppData\Local\Programs\Python\Python311\Lib\site-packages\django\contrib\auth\mixins.py", line 73, in dispatch
    return super().dispatch(request, *args, **kwargs)
           ^^^^^^^^^^^^^^^^^^^^^^^^^^^^^^^^^^^^^^^^^^
  File "C:\Users\administrator\AppData\Local\Programs\Python\Python311\Lib\site-packages\django\views\generic\base.py", line 143, in dispatch
    return handler(request, *args, **kwargs)
           ^^^^^^^^^^^^^^^^^^^^^^^^^^^^^^^^^
  File "C:\Users\administrator\Documents\NTTCS_Control_Framework\NTTCS_CF_project\homepage\views.py", line 308, in post
    request, context = self.contextTotal(request, select, assSelect, context)
                       ^^^^^^^^^^^^^^^^^^^^^^^^^^^^^^^^^^^^^^^^^^^^^^^^^^^^^^
  File "C:\Users\administrator\Documents\NTTCS_Control_Framework\NTTCS_CF_project\homepage\views.py", line 266, in contextTotal
    c = Evidencias.objects.get(evidencia_id=i)
        ^^^^^^^^^^^^^^^^^^^^^^^^^^^^^^^^^^^^^^
  File "C:\Users\administrator\AppData\Local\Programs\Python\Python311\Lib\site-packages\django\db\models\manager.py", line 87, in manager_method
    return getattr(self.get_queryset(), name)(*args, **kwargs)
           ^^^^^^^^^^^^^^^^^^^^^^^^^^^^^^^^^^^^^^^^^^^^^^^^^^^
  File "C:\Users\administrator\AppData\Local\Programs\Python\Python311\Lib\site-packages\django\db\models\query.py", line 637, in get
    raise self.model.DoesNotExist(
homepage.models.Evidencias.DoesNotExist: Evidencias matching query does not exist.
[20/Jul/2023 10:24:50] "POST /assessment/ HTTP/1.1" 500 107174
C:\Users\administrator\Documents\NTTCS_Control_Framework\NTTCS_CF_project\homepage\views.py changed, reloading.
Performing system checks...

System check identified no issues (0 silenced).
July 20, 2023 - 10:23:14
Django version 4.2.2, using settings 'NTTCS_CF_project.settings'
Starting development server at http://127.0.0.1:9242/
Quit the server with CTRL-BREAK.

NTT-AST-02.5
Watching for file changes with StatReloader
[20/Jul/2023 10:26:53] "GET /menu/ HTTP/1.1" 200 9360
[20/Jul/2023 10:26:54] "GET /assessmentselect/ HTTP/1.1" 200 21358
[20/Jul/2023 10:26:56] "POST /assessmentselect/ HTTP/1.1" 302 0
[20/Jul/2023 10:26:56] "GET /assessment/ HTTP/1.1" 200 46824
[20/Jul/2023 10:26:59] "POST /assessment/ HTTP/1.1" 200 51887
[20/Jul/2023 10:27:02] "POST /assessment/ HTTP/1.1" 200 51735
[20/Jul/2023 10:27:12] "POST /assessment/ HTTP/1.1" 200 51887
[20/Jul/2023 10:27:52] "POST /assessment/ HTTP/1.1" 200 52207
[20/Jul/2023 10:28:31] "POST /assessment/ HTTP/1.1" 200 51980
[20/Jul/2023 10:28:41] "POST /assessment/ HTTP/1.1" 200 52068
[20/Jul/2023 10:28:52] "POST /assessment/ HTTP/1.1" 200 57559
[20/Jul/2023 10:29:07] "POST /assessment/ HTTP/1.1" 200 57534
[20/Jul/2023 10:29:14] "POST /assessment/ HTTP/1.1" 200 51340
[20/Jul/2023 10:29:18] "POST /assessment/ HTTP/1.1" 200 51735
[20/Jul/2023 10:29:23] "POST /assessment/ HTTP/1.1" 200 52068
C:\Users\administrator\Documents\NTTCS_Control_Framework\NTTCS_CF_project\homepage\views.py changed, reloading.
Performing system checks...

System check identified no issues (0 silenced).
July 20, 2023 - 10:26:49
Django version 4.2.2, using settings 'NTTCS_CF_project.settings'
Starting development server at http://127.0.0.1:9242/
Quit the server with CTRL-BREAK.

NTT-AST-02.5
NTT-AST-02.5
NTT-AST-02.5
Watching for file changes with StatReloader
Exception in thread django-main-thread:
Traceback (most recent call last):
  File "C:\Users\administrator\AppData\Local\Programs\Python\Python311\Lib\threading.py", line 1038, in _bootstrap_inner
    self.run()
  File "C:\Users\administrator\AppData\Local\Programs\Python\Python311\Lib\threading.py", line 975, in run
    self._target(*self._args, **self._kwargs)
  File "C:\Users\administrator\AppData\Local\Programs\Python\Python311\Lib\site-packages\django\utils\autoreload.py", line 64, in wrapper
    fn(*args, **kwargs)
  File "C:\Users\administrator\AppData\Local\Programs\Python\Python311\Lib\site-packages\django\core\management\commands\runserver.py", line 133, in inner_run
    self.check(display_num_errors=True)
  File "C:\Users\administrator\AppData\Local\Programs\Python\Python311\Lib\site-packages\django\core\management\base.py", line 485, in check
    all_issues = checks.run_checks(
                 ^^^^^^^^^^^^^^^^^^
  File "C:\Users\administrator\AppData\Local\Programs\Python\Python311\Lib\site-packages\django\core\checks\registry.py", line 88, in run_checks
    new_errors = check(app_configs=app_configs, databases=databases)
                 ^^^^^^^^^^^^^^^^^^^^^^^^^^^^^^^^^^^^^^^^^^^^^^^^^^^
  File "C:\Users\administrator\AppData\Local\Programs\Python\Python311\Lib\site-packages\django\core\checks\urls.py", line 42, in check_url_namespaces_unique
    all_namespaces = _load_all_namespaces(resolver)
                     ^^^^^^^^^^^^^^^^^^^^^^^^^^^^^^
  File "C:\Users\administrator\AppData\Local\Programs\Python\Python311\Lib\site-packages\django\core\checks\urls.py", line 61, in _load_all_namespaces
    url_patterns = getattr(resolver, "url_patterns", [])
                   ^^^^^^^^^^^^^^^^^^^^^^^^^^^^^^^^^^^^^
  File "C:\Users\administrator\AppData\Local\Programs\Python\Python311\Lib\site-packages\django\utils\functional.py", line 57, in __get__
    res = instance.__dict__[self.name] = self.func(instance)
                                         ^^^^^^^^^^^^^^^^^^^
  File "C:\Users\administrator\AppData\Local\Programs\Python\Python311\Lib\site-packages\django\urls\resolvers.py", line 715, in url_patterns
    patterns = getattr(self.urlconf_module, "urlpatterns", self.urlconf_module)
                       ^^^^^^^^^^^^^^^^^^^
  File "C:\Users\administrator\AppData\Local\Programs\Python\Python311\Lib\site-packages\django\utils\functional.py", line 57, in __get__
    res = instance.__dict__[self.name] = self.func(instance)
                                         ^^^^^^^^^^^^^^^^^^^
  File "C:\Users\administrator\AppData\Local\Programs\Python\Python311\Lib\site-packages\django\urls\resolvers.py", line 708, in urlconf_module
    return import_module(self.urlconf_name)
           ^^^^^^^^^^^^^^^^^^^^^^^^^^^^^^^^
  File "C:\Users\administrator\AppData\Local\Programs\Python\Python311\Lib\importlib\__init__.py", line 126, in import_module
    return _bootstrap._gcd_import(name[level:], package, level)
           ^^^^^^^^^^^^^^^^^^^^^^^^^^^^^^^^^^^^^^^^^^^^^^^^^^^^
  File "<frozen importlib._bootstrap>", line 1204, in _gcd_import
  File "<frozen importlib._bootstrap>", line 1176, in _find_and_load
  File "<frozen importlib._bootstrap>", line 1147, in _find_and_load_unlocked
  File "<frozen importlib._bootstrap>", line 690, in _load_unlocked
  File "<frozen importlib._bootstrap_external>", line 940, in exec_module
  File "<frozen importlib._bootstrap>", line 241, in _call_with_frames_removed
  File "C:\Users\administrator\Documents\NTTCS_Control_Framework\NTTCS_CF_project\NTTCS_CF_project\urls.py", line 22, in <module>
    path('', include('homepage.urls')),
             ^^^^^^^^^^^^^^^^^^^^^^^^
  File "C:\Users\administrator\AppData\Local\Programs\Python\Python311\Lib\site-packages\django\urls\conf.py", line 38, in include
    urlconf_module = import_module(urlconf_module)
                     ^^^^^^^^^^^^^^^^^^^^^^^^^^^^^
  File "C:\Users\administrator\AppData\Local\Programs\Python\Python311\Lib\importlib\__init__.py", line 126, in import_module
    return _bootstrap._gcd_import(name[level:], package, level)
           ^^^^^^^^^^^^^^^^^^^^^^^^^^^^^^^^^^^^^^^^^^^^^^^^^^^^
  File "<frozen importlib._bootstrap>", line 1204, in _gcd_import
  File "<frozen importlib._bootstrap>", line 1176, in _find_and_load
  File "<frozen importlib._bootstrap>", line 1147, in _find_and_load_unlocked
  File "<frozen importlib._bootstrap>", line 690, in _load_unlocked
  File "<frozen importlib._bootstrap_external>", line 940, in exec_module
  File "<frozen importlib._bootstrap>", line 241, in _call_with_frames_removed
  File "C:\Users\administrator\Documents\NTTCS_Control_Framework\NTTCS_CF_project\homepage\urls.py", line 2, in <module>
    from . import views
  File "C:\Users\administrator\Documents\NTTCS_Control_Framework\NTTCS_CF_project\homepage\views.py", line 1126
    finally:
    ^^^^^^^
SyntaxError: invalid syntax
C:\Users\administrator\Documents\NTTCS_Control_Framework\NTTCS_CF_project\homepage\views.py changed, reloading.
Performing system checks...

Watching for file changes with StatReloader
Exception in thread django-main-thread:
Traceback (most recent call last):
  File "C:\Users\administrator\AppData\Local\Programs\Python\Python311\Lib\threading.py", line 1038, in _bootstrap_inner
    self.run()
  File "C:\Users\administrator\AppData\Local\Programs\Python\Python311\Lib\threading.py", line 975, in run
    self._target(*self._args, **self._kwargs)
  File "C:\Users\administrator\AppData\Local\Programs\Python\Python311\Lib\site-packages\django\utils\autoreload.py", line 64, in wrapper
    fn(*args, **kwargs)
  File "C:\Users\administrator\AppData\Local\Programs\Python\Python311\Lib\site-packages\django\core\management\commands\runserver.py", line 133, in inner_run
    self.check(display_num_errors=True)
  File "C:\Users\administrator\AppData\Local\Programs\Python\Python311\Lib\site-packages\django\core\management\base.py", line 485, in check
    all_issues = checks.run_checks(
                 ^^^^^^^^^^^^^^^^^^
  File "C:\Users\administrator\AppData\Local\Programs\Python\Python311\Lib\site-packages\django\core\checks\registry.py", line 88, in run_checks
    new_errors = check(app_configs=app_configs, databases=databases)
                 ^^^^^^^^^^^^^^^^^^^^^^^^^^^^^^^^^^^^^^^^^^^^^^^^^^^
  File "C:\Users\administrator\AppData\Local\Programs\Python\Python311\Lib\site-packages\django\core\checks\urls.py", line 42, in check_url_namespaces_unique
    all_namespaces = _load_all_namespaces(resolver)
                     ^^^^^^^^^^^^^^^^^^^^^^^^^^^^^^
  File "C:\Users\administrator\AppData\Local\Programs\Python\Python311\Lib\site-packages\django\core\checks\urls.py", line 61, in _load_all_namespaces
    url_patterns = getattr(resolver, "url_patterns", [])
                   ^^^^^^^^^^^^^^^^^^^^^^^^^^^^^^^^^^^^^
  File "C:\Users\administrator\AppData\Local\Programs\Python\Python311\Lib\site-packages\django\utils\functional.py", line 57, in __get__
    res = instance.__dict__[self.name] = self.func(instance)
                                         ^^^^^^^^^^^^^^^^^^^
  File "C:\Users\administrator\AppData\Local\Programs\Python\Python311\Lib\site-packages\django\urls\resolvers.py", line 715, in url_patterns
    patterns = getattr(self.urlconf_module, "urlpatterns", self.urlconf_module)
                       ^^^^^^^^^^^^^^^^^^^
  File "C:\Users\administrator\AppData\Local\Programs\Python\Python311\Lib\site-packages\django\utils\functional.py", line 57, in __get__
    res = instance.__dict__[self.name] = self.func(instance)
                                         ^^^^^^^^^^^^^^^^^^^
  File "C:\Users\administrator\AppData\Local\Programs\Python\Python311\Lib\site-packages\django\urls\resolvers.py", line 708, in urlconf_module
    return import_module(self.urlconf_name)
           ^^^^^^^^^^^^^^^^^^^^^^^^^^^^^^^^
  File "C:\Users\administrator\AppData\Local\Programs\Python\Python311\Lib\importlib\__init__.py", line 126, in import_module
    return _bootstrap._gcd_import(name[level:], package, level)
           ^^^^^^^^^^^^^^^^^^^^^^^^^^^^^^^^^^^^^^^^^^^^^^^^^^^^
  File "<frozen importlib._bootstrap>", line 1204, in _gcd_import
  File "<frozen importlib._bootstrap>", line 1176, in _find_and_load
  File "<frozen importlib._bootstrap>", line 1147, in _find_and_load_unlocked
  File "<frozen importlib._bootstrap>", line 690, in _load_unlocked
  File "<frozen importlib._bootstrap_external>", line 940, in exec_module
  File "<frozen importlib._bootstrap>", line 241, in _call_with_frames_removed
  File "C:\Users\administrator\Documents\NTTCS_Control_Framework\NTTCS_CF_project\NTTCS_CF_project\urls.py", line 22, in <module>
    path('', include('homepage.urls')),
             ^^^^^^^^^^^^^^^^^^^^^^^^
  File "C:\Users\administrator\AppData\Local\Programs\Python\Python311\Lib\site-packages\django\urls\conf.py", line 38, in include
    urlconf_module = import_module(urlconf_module)
                     ^^^^^^^^^^^^^^^^^^^^^^^^^^^^^
  File "C:\Users\administrator\AppData\Local\Programs\Python\Python311\Lib\importlib\__init__.py", line 126, in import_module
    return _bootstrap._gcd_import(name[level:], package, level)
           ^^^^^^^^^^^^^^^^^^^^^^^^^^^^^^^^^^^^^^^^^^^^^^^^^^^^
  File "<frozen importlib._bootstrap>", line 1204, in _gcd_import
  File "<frozen importlib._bootstrap>", line 1176, in _find_and_load
  File "<frozen importlib._bootstrap>", line 1147, in _find_and_load_unlocked
  File "<frozen importlib._bootstrap>", line 690, in _load_unlocked
  File "<frozen importlib._bootstrap_external>", line 940, in exec_module
  File "<frozen importlib._bootstrap>", line 241, in _call_with_frames_removed
  File "C:\Users\administrator\Documents\NTTCS_Control_Framework\NTTCS_CF_project\homepage\urls.py", line 2, in <module>
    from . import views
  File "C:\Users\administrator\Documents\NTTCS_Control_Framework\NTTCS_CF_project\homepage\views.py", line 1126
    finally:
    ^^^^^^^
SyntaxError: invalid syntax
C:\Users\administrator\Documents\NTTCS_Control_Framework\NTTCS_CF_project\homepage\views.py changed, reloading.
Performing system checks...

Watching for file changes with StatReloader
[20/Jul/2023 10:30:29] "GET /menu/ HTTP/1.1" 200 9360
[20/Jul/2023 10:30:30] "GET /assessmentselect/ HTTP/1.1" 200 21358
[20/Jul/2023 10:30:32] "POST /assessmentselect/ HTTP/1.1" 302 0
[20/Jul/2023 10:30:32] "GET /assessment/ HTTP/1.1" 200 46824
[20/Jul/2023 10:30:35] "POST /assessment/ HTTP/1.1" 200 52068
[20/Jul/2023 10:30:47] "POST /assessment/ HTTP/1.1" 200 51735
[20/Jul/2023 10:31:06] "POST /assessment/ HTTP/1.1" 200 51735
[20/Jul/2023 10:31:12] "POST /assessment/ HTTP/1.1" 200 52068
[20/Jul/2023 10:31:16] "POST /assessment/ HTTP/1.1" 200 51735
C:\Users\administrator\Documents\NTTCS_Control_Framework\NTTCS_CF_project\homepage\views.py changed, reloading.
Performing system checks...

System check identified no issues (0 silenced).
July 20, 2023 - 10:30:16
Django version 4.2.2, using settings 'NTTCS_CF_project.settings'
Starting development server at http://127.0.0.1:9242/
Quit the server with CTRL-BREAK.

Watching for file changes with StatReloader
[20/Jul/2023 10:31:31] "POST /assessment/ HTTP/1.1" 200 57559
[20/Jul/2023 10:31:33] "POST /assessment/ HTTP/1.1" 200 57534
[20/Jul/2023 10:31:35] "POST /assessment/ HTTP/1.1" 200 51340
[20/Jul/2023 10:31:37] "POST /assessment/ HTTP/1.1" 200 51735
[20/Jul/2023 10:31:43] "POST /assessment/ HTTP/1.1" 200 52068
C:\Users\administrator\Documents\NTTCS_Control_Framework\NTTCS_CF_project\homepage\views.py changed, reloading.
Performing system checks...

System check identified no issues (0 silenced).
July 20, 2023 - 10:31:30
Django version 4.2.2, using settings 'NTTCS_CF_project.settings'
Starting development server at http://127.0.0.1:9242/
Quit the server with CTRL-BREAK.

Watching for file changes with StatReloader
[20/Jul/2023 10:32:43] "POST /assessment/ HTTP/1.1" 200 52289
[20/Jul/2023 10:33:02] "POST /assessment/ HTTP/1.1" 200 52609
[20/Jul/2023 10:33:22] "POST /assessment/ HTTP/1.1" 200 52410
C:\Users\administrator\Documents\NTTCS_Control_Framework\NTTCS_CF_project\homepage\views.py changed, reloading.
Performing system checks...

System check identified no issues (0 silenced).
July 20, 2023 - 10:31:57
Django version 4.2.2, using settings 'NTTCS_CF_project.settings'
Starting development server at http://127.0.0.1:9242/
Quit the server with CTRL-BREAK.

NTT-AST-02.5
NTT-AST-02.5
Watching for file changes with StatReloader
[20/Jul/2023 10:33:33] "POST /assessment/ HTTP/1.1" 200 57559
C:\Users\administrator\Documents\NTTCS_Control_Framework\NTTCS_CF_project\homepage\views.py changed, reloading.
Performing system checks...

System check identified no issues (0 silenced).
July 20, 2023 - 10:33:27
Django version 4.2.2, using settings 'NTTCS_CF_project.settings'
Starting development server at http://127.0.0.1:9242/
Quit the server with CTRL-BREAK.

Watching for file changes with StatReloader
[20/Jul/2023 10:33:44] "GET /assessmentselect/ HTTP/1.1" 200 21358
[20/Jul/2023 10:33:48] "POST /assessment/ HTTP/1.1" 200 57534
[20/Jul/2023 10:33:51] "GET /assessmentselect/ HTTP/1.1" 200 21358
[20/Jul/2023 10:33:51] "GET /staticfiles/css/estilos.css HTTP/1.1" 304 0
[20/Jul/2023 10:33:53] "POST /assessment/ HTTP/1.1" 200 51340
[20/Jul/2023 10:33:55] "POST /assessment/ HTTP/1.1" 200 51735
Internal Server Error: /MantenimientoAssessmentArchivados/
Traceback (most recent call last):
  File "C:\Users\administrator\AppData\Local\Programs\Python\Python311\Lib\site-packages\django\core\handlers\exception.py", line 55, in inner
    response = get_response(request)
               ^^^^^^^^^^^^^^^^^^^^^
  File "C:\Users\administrator\AppData\Local\Programs\Python\Python311\Lib\site-packages\django\core\handlers\base.py", line 197, in _get_response
    response = wrapped_callback(request, *callback_args, **callback_kwargs)
               ^^^^^^^^^^^^^^^^^^^^^^^^^^^^^^^^^^^^^^^^^^^^^^^^^^^^^^^^^^^^
  File "C:\Users\administrator\AppData\Local\Programs\Python\Python311\Lib\site-packages\django\views\generic\base.py", line 104, in view
    return self.dispatch(request, *args, **kwargs)
           ^^^^^^^^^^^^^^^^^^^^^^^^^^^^^^^^^^^^^^^
  File "C:\Users\administrator\AppData\Local\Programs\Python\Python311\Lib\site-packages\django\contrib\auth\mixins.py", line 73, in dispatch
    return super().dispatch(request, *args, **kwargs)
           ^^^^^^^^^^^^^^^^^^^^^^^^^^^^^^^^^^^^^^^^^^
  File "C:\Users\administrator\AppData\Local\Programs\Python\Python311\Lib\site-packages\django\views\generic\base.py", line 143, in dispatch
    return handler(request, *args, **kwargs)
           ^^^^^^^^^^^^^^^^^^^^^^^^^^^^^^^^^
  File "C:\Users\administrator\AppData\Local\Programs\Python\Python311\Lib\site-packages\django\views\generic\base.py", line 226, in get
    context = self.get_context_data(**kwargs)
              ^^^^^^^^^^^^^^^^^^^^^^^^^^^^^^^
  File "C:\Users\administrator\Documents\NTTCS_Control_Framework\NTTCS_CF_project\homepage\views.py", line 1153, in get_context_data
    s = Assessmentguardados.objects.get(archivado=1)
        ^^^^^^^^^^^^^^^^^^^^^^^^^^^^^^^^^^^^^^^^^^^^
  File "C:\Users\administrator\AppData\Local\Programs\Python\Python311\Lib\site-packages\django\db\models\manager.py", line 87, in manager_method
    return getattr(self.get_queryset(), name)(*args, **kwargs)
           ^^^^^^^^^^^^^^^^^^^^^^^^^^^^^^^^^^^^^^^^^^^^^^^^^^^
  File "C:\Users\administrator\AppData\Local\Programs\Python\Python311\Lib\site-packages\django\db\models\query.py", line 637, in get
    raise self.model.DoesNotExist(
homepage.models.Assessmentguardados.DoesNotExist: Assessmentguardados matching query does not exist.
[20/Jul/2023 10:34:00] "GET /MantenimientoAssessmentArchivados/ HTTP/1.1" 500 89507
[20/Jul/2023 10:34:04] "POST /assessment/ HTTP/1.1" 200 52410
[20/Jul/2023 10:34:05] "POST /assessmentselect/ HTTP/1.1" 302 0
[20/Jul/2023 10:34:05] "GET /assessment/ HTTP/1.1" 200 86875
[20/Jul/2023 10:34:08] "POST /assessment/ HTTP/1.1" 302 0
[20/Jul/2023 10:34:08] "GET /menu/ HTTP/1.1" 200 9360
[20/Jul/2023 10:34:15] "GET /MantenimientoAssessmentArchivados/ HTTP/1.1" 200 9931
[20/Jul/2023 10:34:18] "POST /MantenimientoAssessmentArchivados/ HTTP/1.1" 200 3441952
[20/Jul/2023 10:35:10] "POST /assessment/ HTTP/1.1" 200 52662
[20/Jul/2023 10:35:15] "POST /assessment/ HTTP/1.1" 200 52410
[20/Jul/2023 10:35:32] "POST /assessment/ HTTP/1.1" 302 0
[20/Jul/2023 10:35:32] "GET /menu/ HTTP/1.1" 200 9360
[20/Jul/2023 10:35:35] "GET /assessmentselect/ HTTP/1.1" 200 21138
Internal Server Error: /MantenimientoAssessmentArchivados/
Traceback (most recent call last):
  File "C:\Users\administrator\AppData\Local\Programs\Python\Python311\Lib\site-packages\django\core\handlers\exception.py", line 55, in inner
    response = get_response(request)
               ^^^^^^^^^^^^^^^^^^^^^
  File "C:\Users\administrator\AppData\Local\Programs\Python\Python311\Lib\site-packages\django\core\handlers\base.py", line 197, in _get_response
    response = wrapped_callback(request, *callback_args, **callback_kwargs)
               ^^^^^^^^^^^^^^^^^^^^^^^^^^^^^^^^^^^^^^^^^^^^^^^^^^^^^^^^^^^^
  File "C:\Users\administrator\AppData\Local\Programs\Python\Python311\Lib\site-packages\django\views\generic\base.py", line 104, in view
    return self.dispatch(request, *args, **kwargs)
           ^^^^^^^^^^^^^^^^^^^^^^^^^^^^^^^^^^^^^^^
  File "C:\Users\administrator\AppData\Local\Programs\Python\Python311\Lib\site-packages\django\contrib\auth\mixins.py", line 73, in dispatch
    return super().dispatch(request, *args, **kwargs)
           ^^^^^^^^^^^^^^^^^^^^^^^^^^^^^^^^^^^^^^^^^^
  File "C:\Users\administrator\AppData\Local\Programs\Python\Python311\Lib\site-packages\django\views\generic\base.py", line 143, in dispatch
    return handler(request, *args, **kwargs)
           ^^^^^^^^^^^^^^^^^^^^^^^^^^^^^^^^^
  File "C:\Users\administrator\AppData\Local\Programs\Python\Python311\Lib\site-packages\django\views\generic\base.py", line 226, in get
    context = self.get_context_data(**kwargs)
              ^^^^^^^^^^^^^^^^^^^^^^^^^^^^^^^
  File "C:\Users\administrator\Documents\NTTCS_Control_Framework\NTTCS_CF_project\homepage\views.py", line 1153, in get_context_data
    s = Assessmentguardados.objects.get(archivado=1)
        ^^^^^^^^^^^^^^^^^^^^^^^^^^^^^^^^^^^^^^^^^^^^
  File "C:\Users\administrator\AppData\Local\Programs\Python\Python311\Lib\site-packages\django\db\models\manager.py", line 87, in manager_method
    return getattr(self.get_queryset(), name)(*args, **kwargs)
           ^^^^^^^^^^^^^^^^^^^^^^^^^^^^^^^^^^^^^^^^^^^^^^^^^^^
  File "C:\Users\administrator\AppData\Local\Programs\Python\Python311\Lib\site-packages\django\db\models\query.py", line 640, in get
    raise self.model.MultipleObjectsReturned(
homepage.models.Assessmentguardados.MultipleObjectsReturned: get() returned more than one Assessmentguardados -- it returned 2!
[20/Jul/2023 10:35:50] "GET /MantenimientoAssessmentArchivados/ HTTP/1.1" 500 89715
[20/Jul/2023 10:36:07] "GET /assessmentselect/ HTTP/1.1" 200 21138
Internal Server Error: /MantenimientoAssessmentArchivados/
Traceback (most recent call last):
  File "C:\Users\administrator\AppData\Local\Programs\Python\Python311\Lib\site-packages\django\core\handlers\exception.py", line 55, in inner
    response = get_response(request)
               ^^^^^^^^^^^^^^^^^^^^^
  File "C:\Users\administrator\AppData\Local\Programs\Python\Python311\Lib\site-packages\django\core\handlers\base.py", line 197, in _get_response
    response = wrapped_callback(request, *callback_args, **callback_kwargs)
               ^^^^^^^^^^^^^^^^^^^^^^^^^^^^^^^^^^^^^^^^^^^^^^^^^^^^^^^^^^^^
  File "C:\Users\administrator\AppData\Local\Programs\Python\Python311\Lib\site-packages\django\views\generic\base.py", line 104, in view
    return self.dispatch(request, *args, **kwargs)
           ^^^^^^^^^^^^^^^^^^^^^^^^^^^^^^^^^^^^^^^
  File "C:\Users\administrator\AppData\Local\Programs\Python\Python311\Lib\site-packages\django\contrib\auth\mixins.py", line 73, in dispatch
    return super().dispatch(request, *args, **kwargs)
           ^^^^^^^^^^^^^^^^^^^^^^^^^^^^^^^^^^^^^^^^^^
  File "C:\Users\administrator\AppData\Local\Programs\Python\Python311\Lib\site-packages\django\views\generic\base.py", line 143, in dispatch
    return handler(request, *args, **kwargs)
           ^^^^^^^^^^^^^^^^^^^^^^^^^^^^^^^^^
  File "C:\Users\administrator\AppData\Local\Programs\Python\Python311\Lib\site-packages\django\views\generic\base.py", line 226, in get
    context = self.get_context_data(**kwargs)
              ^^^^^^^^^^^^^^^^^^^^^^^^^^^^^^^
  File "C:\Users\administrator\Documents\NTTCS_Control_Framework\NTTCS_CF_project\homepage\views.py", line 1153, in get_context_data
    s = Assessmentguardados.objects.get(archivado=1)
        ^^^^^^^^^^^^^^^^^^^^^^^^^^^^^^^^^^^^^^^^^^^^
  File "C:\Users\administrator\AppData\Local\Programs\Python\Python311\Lib\site-packages\django\db\models\manager.py", line 87, in manager_method
    return getattr(self.get_queryset(), name)(*args, **kwargs)
           ^^^^^^^^^^^^^^^^^^^^^^^^^^^^^^^^^^^^^^^^^^^^^^^^^^^
  File "C:\Users\administrator\AppData\Local\Programs\Python\Python311\Lib\site-packages\django\db\models\query.py", line 640, in get
    raise self.model.MultipleObjectsReturned(
homepage.models.Assessmentguardados.MultipleObjectsReturned: get() returned more than one Assessmentguardados -- it returned 2!
[20/Jul/2023 10:36:12] "GET /MantenimientoAssessmentArchivados/ HTTP/1.1" 500 89814
[20/Jul/2023 10:36:18] "GET /mantenimientoNivelMadurez/ HTTP/1.1" 200 33480
[20/Jul/2023 10:36:20] "GET /assessmentselect/ HTTP/1.1" 200 21138
Internal Server Error: /MantenimientoAssessmentArchivados/
Traceback (most recent call last):
  File "C:\Users\administrator\AppData\Local\Programs\Python\Python311\Lib\site-packages\django\core\handlers\exception.py", line 55, in inner
    response = get_response(request)
               ^^^^^^^^^^^^^^^^^^^^^
  File "C:\Users\administrator\AppData\Local\Programs\Python\Python311\Lib\site-packages\django\core\handlers\base.py", line 197, in _get_response
    response = wrapped_callback(request, *callback_args, **callback_kwargs)
               ^^^^^^^^^^^^^^^^^^^^^^^^^^^^^^^^^^^^^^^^^^^^^^^^^^^^^^^^^^^^
  File "C:\Users\administrator\AppData\Local\Programs\Python\Python311\Lib\site-packages\django\views\generic\base.py", line 104, in view
    return self.dispatch(request, *args, **kwargs)
           ^^^^^^^^^^^^^^^^^^^^^^^^^^^^^^^^^^^^^^^
  File "C:\Users\administrator\AppData\Local\Programs\Python\Python311\Lib\site-packages\django\contrib\auth\mixins.py", line 73, in dispatch
    return super().dispatch(request, *args, **kwargs)
           ^^^^^^^^^^^^^^^^^^^^^^^^^^^^^^^^^^^^^^^^^^
  File "C:\Users\administrator\AppData\Local\Programs\Python\Python311\Lib\site-packages\django\views\generic\base.py", line 143, in dispatch
    return handler(request, *args, **kwargs)
           ^^^^^^^^^^^^^^^^^^^^^^^^^^^^^^^^^
  File "C:\Users\administrator\AppData\Local\Programs\Python\Python311\Lib\site-packages\django\views\generic\base.py", line 226, in get
    context = self.get_context_data(**kwargs)
              ^^^^^^^^^^^^^^^^^^^^^^^^^^^^^^^
  File "C:\Users\administrator\Documents\NTTCS_Control_Framework\NTTCS_CF_project\homepage\views.py", line 1153, in get_context_data
    s = Assessmentguardados.objects.get(archivado=1)
        ^^^^^^^^^^^^^^^^^^^^^^^^^^^^^^^^^^^^^^^^^^^^
  File "C:\Users\administrator\AppData\Local\Programs\Python\Python311\Lib\site-packages\django\db\models\manager.py", line 87, in manager_method
    return getattr(self.get_queryset(), name)(*args, **kwargs)
           ^^^^^^^^^^^^^^^^^^^^^^^^^^^^^^^^^^^^^^^^^^^^^^^^^^^
  File "C:\Users\administrator\AppData\Local\Programs\Python\Python311\Lib\site-packages\django\db\models\query.py", line 640, in get
    raise self.model.MultipleObjectsReturned(
homepage.models.Assessmentguardados.MultipleObjectsReturned: get() returned more than one Assessmentguardados -- it returned 2!
[20/Jul/2023 10:36:23] "GET /MantenimientoAssessmentArchivados/ HTTP/1.1" 500 89715
[20/Jul/2023 10:36:30] "GET /exportaciones/ HTTP/1.1" 200 11524
[20/Jul/2023 10:36:31] "GET /informes/ HTTP/1.1" 200 9384
[20/Jul/2023 10:36:31] "GET /assessmentselect/ HTTP/1.1" 200 21138
[20/Jul/2023 10:36:33] "GET /MantenimientoMapeoMarcos/ HTTP/1.1" 200 20536
[20/Jul/2023 10:36:36] "GET /MantenimientoEvidencias/ HTTP/1.1" 200 279690
[20/Jul/2023 10:36:38] "GET /MantenimientoPreguntas/ HTTP/1.1" 200 1582043
[20/Jul/2023 10:36:39] "GET /informes/ HTTP/1.1" 200 9384
Internal Server Error: /MantenimientoAssessmentArchivados/
Traceback (most recent call last):
  File "C:\Users\administrator\AppData\Local\Programs\Python\Python311\Lib\site-packages\django\core\handlers\exception.py", line 55, in inner
    response = get_response(request)
               ^^^^^^^^^^^^^^^^^^^^^
  File "C:\Users\administrator\AppData\Local\Programs\Python\Python311\Lib\site-packages\django\core\handlers\base.py", line 197, in _get_response
    response = wrapped_callback(request, *callback_args, **callback_kwargs)
               ^^^^^^^^^^^^^^^^^^^^^^^^^^^^^^^^^^^^^^^^^^^^^^^^^^^^^^^^^^^^
  File "C:\Users\administrator\AppData\Local\Programs\Python\Python311\Lib\site-packages\django\views\generic\base.py", line 104, in view
    return self.dispatch(request, *args, **kwargs)
           ^^^^^^^^^^^^^^^^^^^^^^^^^^^^^^^^^^^^^^^
  File "C:\Users\administrator\AppData\Local\Programs\Python\Python311\Lib\site-packages\django\contrib\auth\mixins.py", line 73, in dispatch
    return super().dispatch(request, *args, **kwargs)
           ^^^^^^^^^^^^^^^^^^^^^^^^^^^^^^^^^^^^^^^^^^
  File "C:\Users\administrator\AppData\Local\Programs\Python\Python311\Lib\site-packages\django\views\generic\base.py", line 143, in dispatch
    return handler(request, *args, **kwargs)
           ^^^^^^^^^^^^^^^^^^^^^^^^^^^^^^^^^
  File "C:\Users\administrator\AppData\Local\Programs\Python\Python311\Lib\site-packages\django\views\generic\base.py", line 226, in get
    context = self.get_context_data(**kwargs)
              ^^^^^^^^^^^^^^^^^^^^^^^^^^^^^^^
  File "C:\Users\administrator\Documents\NTTCS_Control_Framework\NTTCS_CF_project\homepage\views.py", line 1153, in get_context_data
    s = Assessmentguardados.objects.get(archivado=1)
        ^^^^^^^^^^^^^^^^^^^^^^^^^^^^^^^^^^^^^^^^^^^^
  File "C:\Users\administrator\AppData\Local\Programs\Python\Python311\Lib\site-packages\django\db\models\manager.py", line 87, in manager_method
    return getattr(self.get_queryset(), name)(*args, **kwargs)
           ^^^^^^^^^^^^^^^^^^^^^^^^^^^^^^^^^^^^^^^^^^^^^^^^^^^
  File "C:\Users\administrator\AppData\Local\Programs\Python\Python311\Lib\site-packages\django\db\models\query.py", line 640, in get
    raise self.model.MultipleObjectsReturned(
homepage.models.Assessmentguardados.MultipleObjectsReturned: get() returned more than one Assessmentguardados -- it returned 2!
[20/Jul/2023 10:36:40] "GET /MantenimientoAssessmentArchivados/ HTTP/1.1" 500 89721
Internal Server Error: /MantenimientoAssessmentArchivados/
Traceback (most recent call last):
  File "C:\Users\administrator\AppData\Local\Programs\Python\Python311\Lib\site-packages\django\core\handlers\exception.py", line 55, in inner
    response = get_response(request)
               ^^^^^^^^^^^^^^^^^^^^^
  File "C:\Users\administrator\AppData\Local\Programs\Python\Python311\Lib\site-packages\django\core\handlers\base.py", line 197, in _get_response
    response = wrapped_callback(request, *callback_args, **callback_kwargs)
               ^^^^^^^^^^^^^^^^^^^^^^^^^^^^^^^^^^^^^^^^^^^^^^^^^^^^^^^^^^^^
  File "C:\Users\administrator\AppData\Local\Programs\Python\Python311\Lib\site-packages\django\views\generic\base.py", line 104, in view
    return self.dispatch(request, *args, **kwargs)
           ^^^^^^^^^^^^^^^^^^^^^^^^^^^^^^^^^^^^^^^
  File "C:\Users\administrator\AppData\Local\Programs\Python\Python311\Lib\site-packages\django\contrib\auth\mixins.py", line 73, in dispatch
    return super().dispatch(request, *args, **kwargs)
           ^^^^^^^^^^^^^^^^^^^^^^^^^^^^^^^^^^^^^^^^^^
  File "C:\Users\administrator\AppData\Local\Programs\Python\Python311\Lib\site-packages\django\views\generic\base.py", line 143, in dispatch
    return handler(request, *args, **kwargs)
           ^^^^^^^^^^^^^^^^^^^^^^^^^^^^^^^^^
  File "C:\Users\administrator\AppData\Local\Programs\Python\Python311\Lib\site-packages\django\views\generic\base.py", line 226, in get
    context = self.get_context_data(**kwargs)
              ^^^^^^^^^^^^^^^^^^^^^^^^^^^^^^^
  File "C:\Users\administrator\Documents\NTTCS_Control_Framework\NTTCS_CF_project\homepage\views.py", line 1153, in get_context_data
    s = Assessmentguardados.objects.get(archivado=1)
        ^^^^^^^^^^^^^^^^^^^^^^^^^^^^^^^^^^^^^^^^^^^^
  File "C:\Users\administrator\AppData\Local\Programs\Python\Python311\Lib\site-packages\django\db\models\manager.py", line 87, in manager_method
    return getattr(self.get_queryset(), name)(*args, **kwargs)
           ^^^^^^^^^^^^^^^^^^^^^^^^^^^^^^^^^^^^^^^^^^^^^^^^^^^
  File "C:\Users\administrator\AppData\Local\Programs\Python\Python311\Lib\site-packages\django\db\models\query.py", line 640, in get
    raise self.model.MultipleObjectsReturned(
homepage.models.Assessmentguardados.MultipleObjectsReturned: get() returned more than one Assessmentguardados -- it returned 2!
[20/Jul/2023 10:36:41] "GET /MantenimientoAssessmentArchivados/ HTTP/1.1" 500 89806
[20/Jul/2023 10:36:49] "GET /informes/ HTTP/1.1" 200 9384
[20/Jul/2023 10:36:52] "GET /exportaciones/ HTTP/1.1" 200 11524
Internal Server Error: /MantenimientoAssessmentArchivados/
Traceback (most recent call last):
  File "C:\Users\administrator\AppData\Local\Programs\Python\Python311\Lib\site-packages\django\core\handlers\exception.py", line 55, in inner
    response = get_response(request)
               ^^^^^^^^^^^^^^^^^^^^^
  File "C:\Users\administrator\AppData\Local\Programs\Python\Python311\Lib\site-packages\django\core\handlers\base.py", line 197, in _get_response
    response = wrapped_callback(request, *callback_args, **callback_kwargs)
               ^^^^^^^^^^^^^^^^^^^^^^^^^^^^^^^^^^^^^^^^^^^^^^^^^^^^^^^^^^^^
  File "C:\Users\administrator\AppData\Local\Programs\Python\Python311\Lib\site-packages\django\views\generic\base.py", line 104, in view
    return self.dispatch(request, *args, **kwargs)
           ^^^^^^^^^^^^^^^^^^^^^^^^^^^^^^^^^^^^^^^
  File "C:\Users\administrator\AppData\Local\Programs\Python\Python311\Lib\site-packages\django\contrib\auth\mixins.py", line 73, in dispatch
    return super().dispatch(request, *args, **kwargs)
           ^^^^^^^^^^^^^^^^^^^^^^^^^^^^^^^^^^^^^^^^^^
  File "C:\Users\administrator\AppData\Local\Programs\Python\Python311\Lib\site-packages\django\views\generic\base.py", line 143, in dispatch
    return handler(request, *args, **kwargs)
           ^^^^^^^^^^^^^^^^^^^^^^^^^^^^^^^^^
  File "C:\Users\administrator\AppData\Local\Programs\Python\Python311\Lib\site-packages\django\views\generic\base.py", line 226, in get
    context = self.get_context_data(**kwargs)
              ^^^^^^^^^^^^^^^^^^^^^^^^^^^^^^^
  File "C:\Users\administrator\Documents\NTTCS_Control_Framework\NTTCS_CF_project\homepage\views.py", line 1153, in get_context_data
    s = Assessmentguardados.objects.get(archivado=1)
        ^^^^^^^^^^^^^^^^^^^^^^^^^^^^^^^^^^^^^^^^^^^^
  File "C:\Users\administrator\AppData\Local\Programs\Python\Python311\Lib\site-packages\django\db\models\manager.py", line 87, in manager_method
    return getattr(self.get_queryset(), name)(*args, **kwargs)
           ^^^^^^^^^^^^^^^^^^^^^^^^^^^^^^^^^^^^^^^^^^^^^^^^^^^
  File "C:\Users\administrator\AppData\Local\Programs\Python\Python311\Lib\site-packages\django\db\models\query.py", line 640, in get
    raise self.model.MultipleObjectsReturned(
homepage.models.Assessmentguardados.MultipleObjectsReturned: get() returned more than one Assessmentguardados -- it returned 2!
[20/Jul/2023 10:36:59] "GET /MantenimientoAssessmentArchivados/ HTTP/1.1" 500 89712
Internal Server Error: /MantenimientoAssessmentArchivados/
Traceback (most recent call last):
  File "C:\Users\administrator\AppData\Local\Programs\Python\Python311\Lib\site-packages\django\core\handlers\exception.py", line 55, in inner
    response = get_response(request)
               ^^^^^^^^^^^^^^^^^^^^^
  File "C:\Users\administrator\AppData\Local\Programs\Python\Python311\Lib\site-packages\django\core\handlers\base.py", line 197, in _get_response
    response = wrapped_callback(request, *callback_args, **callback_kwargs)
               ^^^^^^^^^^^^^^^^^^^^^^^^^^^^^^^^^^^^^^^^^^^^^^^^^^^^^^^^^^^^
  File "C:\Users\administrator\AppData\Local\Programs\Python\Python311\Lib\site-packages\django\views\generic\base.py", line 104, in view
    return self.dispatch(request, *args, **kwargs)
           ^^^^^^^^^^^^^^^^^^^^^^^^^^^^^^^^^^^^^^^
  File "C:\Users\administrator\AppData\Local\Programs\Python\Python311\Lib\site-packages\django\contrib\auth\mixins.py", line 73, in dispatch
    return super().dispatch(request, *args, **kwargs)
           ^^^^^^^^^^^^^^^^^^^^^^^^^^^^^^^^^^^^^^^^^^
  File "C:\Users\administrator\AppData\Local\Programs\Python\Python311\Lib\site-packages\django\views\generic\base.py", line 143, in dispatch
    return handler(request, *args, **kwargs)
           ^^^^^^^^^^^^^^^^^^^^^^^^^^^^^^^^^
  File "C:\Users\administrator\AppData\Local\Programs\Python\Python311\Lib\site-packages\django\views\generic\base.py", line 226, in get
    context = self.get_context_data(**kwargs)
              ^^^^^^^^^^^^^^^^^^^^^^^^^^^^^^^
  File "C:\Users\administrator\Documents\NTTCS_Control_Framework\NTTCS_CF_project\homepage\views.py", line 1153, in get_context_data
    s = Assessmentguardados.objects.get(archivado=1)
        ^^^^^^^^^^^^^^^^^^^^^^^^^^^^^^^^^^^^^^^^^^^^
  File "C:\Users\administrator\AppData\Local\Programs\Python\Python311\Lib\site-packages\django\db\models\manager.py", line 87, in manager_method
    return getattr(self.get_queryset(), name)(*args, **kwargs)
           ^^^^^^^^^^^^^^^^^^^^^^^^^^^^^^^^^^^^^^^^^^^^^^^^^^^
  File "C:\Users\administrator\AppData\Local\Programs\Python\Python311\Lib\site-packages\django\db\models\query.py", line 640, in get
    raise self.model.MultipleObjectsReturned(
homepage.models.Assessmentguardados.MultipleObjectsReturned: get() returned more than one Assessmentguardados -- it returned 2!
[20/Jul/2023 10:37:27] "GET /MantenimientoAssessmentArchivados/ HTTP/1.1" 500 89712
Internal Server Error: /MantenimientoAssessmentArchivados/
Traceback (most recent call last):
  File "C:\Users\administrator\AppData\Local\Programs\Python\Python311\Lib\site-packages\django\core\handlers\exception.py", line 55, in inner
    response = get_response(request)
               ^^^^^^^^^^^^^^^^^^^^^
  File "C:\Users\administrator\AppData\Local\Programs\Python\Python311\Lib\site-packages\django\core\handlers\base.py", line 197, in _get_response
    response = wrapped_callback(request, *callback_args, **callback_kwargs)
               ^^^^^^^^^^^^^^^^^^^^^^^^^^^^^^^^^^^^^^^^^^^^^^^^^^^^^^^^^^^^
  File "C:\Users\administrator\AppData\Local\Programs\Python\Python311\Lib\site-packages\django\views\generic\base.py", line 104, in view
    return self.dispatch(request, *args, **kwargs)
           ^^^^^^^^^^^^^^^^^^^^^^^^^^^^^^^^^^^^^^^
  File "C:\Users\administrator\AppData\Local\Programs\Python\Python311\Lib\site-packages\django\contrib\auth\mixins.py", line 73, in dispatch
    return super().dispatch(request, *args, **kwargs)
           ^^^^^^^^^^^^^^^^^^^^^^^^^^^^^^^^^^^^^^^^^^
  File "C:\Users\administrator\AppData\Local\Programs\Python\Python311\Lib\site-packages\django\views\generic\base.py", line 143, in dispatch
    return handler(request, *args, **kwargs)
           ^^^^^^^^^^^^^^^^^^^^^^^^^^^^^^^^^
  File "C:\Users\administrator\AppData\Local\Programs\Python\Python311\Lib\site-packages\django\views\generic\base.py", line 226, in get
    context = self.get_context_data(**kwargs)
              ^^^^^^^^^^^^^^^^^^^^^^^^^^^^^^^
  File "C:\Users\administrator\Documents\NTTCS_Control_Framework\NTTCS_CF_project\homepage\views.py", line 1153, in get_context_data
    s = Assessmentguardados.objects.get(archivado=1)
        ^^^^^^^^^^^^^^^^^^^^^^^^^^^^^^^^^^^^^^^^^^^^
  File "C:\Users\administrator\AppData\Local\Programs\Python\Python311\Lib\site-packages\django\db\models\manager.py", line 87, in manager_method
    return getattr(self.get_queryset(), name)(*args, **kwargs)
           ^^^^^^^^^^^^^^^^^^^^^^^^^^^^^^^^^^^^^^^^^^^^^^^^^^^
  File "C:\Users\administrator\AppData\Local\Programs\Python\Python311\Lib\site-packages\django\db\models\query.py", line 640, in get
    raise self.model.MultipleObjectsReturned(
homepage.models.Assessmentguardados.MultipleObjectsReturned: get() returned more than one Assessmentguardados -- it returned 2!
[20/Jul/2023 10:37:31] "GET /MantenimientoAssessmentArchivados/ HTTP/1.1" 500 89712
C:\Users\administrator\Documents\NTTCS_Control_Framework\NTTCS_CF_project\homepage\views.py changed, reloading.
Performing system checks...

System check identified no issues (0 silenced).
July 20, 2023 - 10:33:35
Django version 4.2.2, using settings 'NTTCS_CF_project.settings'
Starting development server at http://127.0.0.1:9242/
Quit the server with CTRL-BREAK.

Watching for file changes with StatReloader
C:\Users\administrator\Documents\NTTCS_Control_Framework\NTTCS_CF_project\homepage\views.py changed, reloading.
Performing system checks...

System check identified no issues (0 silenced).
July 20, 2023 - 10:38:14
Django version 4.2.2, using settings 'NTTCS_CF_project.settings'
Starting development server at http://127.0.0.1:9242/
Quit the server with CTRL-BREAK.

Watching for file changes with StatReloader
[20/Jul/2023 10:38:26] "GET /menu/ HTTP/1.1" 200 9360
[20/Jul/2023 10:38:28] "GET /MantenimientoAssessmentArchivados/ HTTP/1.1" 200 10068
Internal Server Error: /MantenimientoAssessmentArchivados/
Traceback (most recent call last):
  File "C:\Users\administrator\AppData\Local\Programs\Python\Python311\Lib\site-packages\django\core\handlers\exception.py", line 55, in inner
    response = get_response(request)
               ^^^^^^^^^^^^^^^^^^^^^
  File "C:\Users\administrator\AppData\Local\Programs\Python\Python311\Lib\site-packages\django\core\handlers\base.py", line 197, in _get_response
    response = wrapped_callback(request, *callback_args, **callback_kwargs)
               ^^^^^^^^^^^^^^^^^^^^^^^^^^^^^^^^^^^^^^^^^^^^^^^^^^^^^^^^^^^^
  File "C:\Users\administrator\AppData\Local\Programs\Python\Python311\Lib\site-packages\django\views\generic\base.py", line 104, in view
    return self.dispatch(request, *args, **kwargs)
           ^^^^^^^^^^^^^^^^^^^^^^^^^^^^^^^^^^^^^^^
  File "C:\Users\administrator\AppData\Local\Programs\Python\Python311\Lib\site-packages\django\contrib\auth\mixins.py", line 73, in dispatch
    return super().dispatch(request, *args, **kwargs)
           ^^^^^^^^^^^^^^^^^^^^^^^^^^^^^^^^^^^^^^^^^^
  File "C:\Users\administrator\AppData\Local\Programs\Python\Python311\Lib\site-packages\django\views\generic\base.py", line 143, in dispatch
    return handler(request, *args, **kwargs)
           ^^^^^^^^^^^^^^^^^^^^^^^^^^^^^^^^^
  File "C:\Users\administrator\Documents\NTTCS_Control_Framework\NTTCS_CF_project\homepage\views.py", line 1059, in post
    s = Assessmentguardados.objects.get(archivado=1)
        ^^^^^^^^^^^^^^^^^^^^^^^^^^^^^^^^^^^^^^^^^^^^
  File "C:\Users\administrator\AppData\Local\Programs\Python\Python311\Lib\site-packages\django\db\models\manager.py", line 87, in manager_method
    return getattr(self.get_queryset(), name)(*args, **kwargs)
           ^^^^^^^^^^^^^^^^^^^^^^^^^^^^^^^^^^^^^^^^^^^^^^^^^^^
  File "C:\Users\administrator\AppData\Local\Programs\Python\Python311\Lib\site-packages\django\db\models\query.py", line 640, in get
    raise self.model.MultipleObjectsReturned(
homepage.models.Assessmentguardados.MultipleObjectsReturned: get() returned more than one Assessmentguardados -- it returned 2!
[20/Jul/2023 10:38:32] "POST /MantenimientoAssessmentArchivados/ HTTP/1.1" 500 86970
C:\Users\administrator\Documents\NTTCS_Control_Framework\NTTCS_CF_project\homepage\views.py changed, reloading.
Performing system checks...

System check identified no issues (0 silenced).
July 20, 2023 - 10:38:23
Django version 4.2.2, using settings 'NTTCS_CF_project.settings'
Starting development server at http://127.0.0.1:9242/
Quit the server with CTRL-BREAK.

Watching for file changes with StatReloader
C:\Users\administrator\Documents\NTTCS_Control_Framework\NTTCS_CF_project\homepage\views.py changed, reloading.
Performing system checks...

System check identified no issues (0 silenced).
July 20, 2023 - 10:38:51
Django version 4.2.2, using settings 'NTTCS_CF_project.settings'
Starting development server at http://127.0.0.1:9242/
Quit the server with CTRL-BREAK.

Watching for file changes with StatReloader
[20/Jul/2023 10:38:57] "GET /MantenimientoAssessmentArchivados/ HTTP/1.1" 200 10068
[20/Jul/2023 10:38:59] "GET /MantenimientoAssessmentArchivados/ HTTP/1.1" 200 10068
[20/Jul/2023 10:39:04] "GET /menu/ HTTP/1.1" 200 9360
[20/Jul/2023 10:39:05] "GET /MantenimientoAssessmentArchivados/ HTTP/1.1" 200 10068
[20/Jul/2023 10:39:08] "POST /MantenimientoAssessmentArchivados/ HTTP/1.1" 200 1475320
Internal Server Error: /MantenimientoAssessmentArchivados/
Traceback (most recent call last):
  File "C:\Users\administrator\AppData\Local\Programs\Python\Python311\Lib\site-packages\mysql\connector\connection_cext.py", line 611, in cmd_query
    self._cmysql.query(
_mysql_connector.MySQLInterfaceError: Table 'nttcs_cf.pruebaassess2' doesn't exist

The above exception was the direct cause of the following exception:

Traceback (most recent call last):
  File "C:\Users\administrator\AppData\Local\Programs\Python\Python311\Lib\site-packages\django\core\handlers\exception.py", line 55, in inner
    response = get_response(request)
               ^^^^^^^^^^^^^^^^^^^^^
  File "C:\Users\administrator\AppData\Local\Programs\Python\Python311\Lib\site-packages\django\core\handlers\base.py", line 197, in _get_response
    response = wrapped_callback(request, *callback_args, **callback_kwargs)
               ^^^^^^^^^^^^^^^^^^^^^^^^^^^^^^^^^^^^^^^^^^^^^^^^^^^^^^^^^^^^
  File "C:\Users\administrator\AppData\Local\Programs\Python\Python311\Lib\site-packages\django\views\generic\base.py", line 104, in view
    return self.dispatch(request, *args, **kwargs)
           ^^^^^^^^^^^^^^^^^^^^^^^^^^^^^^^^^^^^^^^
  File "C:\Users\administrator\AppData\Local\Programs\Python\Python311\Lib\site-packages\django\contrib\auth\mixins.py", line 73, in dispatch
    return super().dispatch(request, *args, **kwargs)
           ^^^^^^^^^^^^^^^^^^^^^^^^^^^^^^^^^^^^^^^^^^
  File "C:\Users\administrator\AppData\Local\Programs\Python\Python311\Lib\site-packages\django\views\generic\base.py", line 143, in dispatch
    return handler(request, *args, **kwargs)
           ^^^^^^^^^^^^^^^^^^^^^^^^^^^^^^^^^
  File "C:\Users\administrator\Documents\NTTCS_Control_Framework\NTTCS_CF_project\homepage\views.py", line 1056, in post
    mycursor.execute("SELECT * FROM " + selector)  # realizamos la consulta para obtener los contrloles
    ^^^^^^^^^^^^^^^^^^^^^^^^^^^^^^^^^^^^^^^^^^^^^
  File "C:\Users\administrator\AppData\Local\Programs\Python\Python311\Lib\site-packages\mysql\connector\cursor_cext.py", line 330, in execute
    result = self._cnx.cmd_query(
             ^^^^^^^^^^^^^^^^^^^^
  File "C:\Users\administrator\AppData\Local\Programs\Python\Python311\Lib\site-packages\mysql\connector\connection_cext.py", line 619, in cmd_query
    raise get_mysql_exception(
mysql.connector.errors.ProgrammingError: 1146 (42S02): Table 'nttcs_cf.pruebaassess2' doesn't exist
[20/Jul/2023 10:39:27] "POST /MantenimientoAssessmentArchivados/ HTTP/1.1" 500 91223
[20/Jul/2023 10:41:37] "POST /MantenimientoAssessmentArchivados/ HTTP/1.1" 200 1475320
Internal Server Error: /MantenimientoAssessmentArchivados/
Traceback (most recent call last):
  File "C:\Users\administrator\AppData\Local\Programs\Python\Python311\Lib\site-packages\mysql\connector\connection_cext.py", line 611, in cmd_query
    self._cmysql.query(
_mysql_connector.MySQLInterfaceError: Table 'nttcs_cf.pruebaassess2' doesn't exist

The above exception was the direct cause of the following exception:

Traceback (most recent call last):
  File "C:\Users\administrator\AppData\Local\Programs\Python\Python311\Lib\site-packages\django\core\handlers\exception.py", line 55, in inner
    response = get_response(request)
               ^^^^^^^^^^^^^^^^^^^^^
  File "C:\Users\administrator\AppData\Local\Programs\Python\Python311\Lib\site-packages\django\core\handlers\base.py", line 197, in _get_response
    response = wrapped_callback(request, *callback_args, **callback_kwargs)
               ^^^^^^^^^^^^^^^^^^^^^^^^^^^^^^^^^^^^^^^^^^^^^^^^^^^^^^^^^^^^
  File "C:\Users\administrator\AppData\Local\Programs\Python\Python311\Lib\site-packages\django\views\generic\base.py", line 104, in view
    return self.dispatch(request, *args, **kwargs)
           ^^^^^^^^^^^^^^^^^^^^^^^^^^^^^^^^^^^^^^^
  File "C:\Users\administrator\AppData\Local\Programs\Python\Python311\Lib\site-packages\django\contrib\auth\mixins.py", line 73, in dispatch
    return super().dispatch(request, *args, **kwargs)
           ^^^^^^^^^^^^^^^^^^^^^^^^^^^^^^^^^^^^^^^^^^
  File "C:\Users\administrator\AppData\Local\Programs\Python\Python311\Lib\site-packages\django\views\generic\base.py", line 143, in dispatch
    return handler(request, *args, **kwargs)
           ^^^^^^^^^^^^^^^^^^^^^^^^^^^^^^^^^
  File "C:\Users\administrator\Documents\NTTCS_Control_Framework\NTTCS_CF_project\homepage\views.py", line 1056, in post
    mycursor.execute("SELECT * FROM " + selector)  # realizamos la consulta para obtener los contrloles
    ^^^^^^^^^^^^^^^^^^^^^^^^^^^^^^^^^^^^^^^^^^^^^
  File "C:\Users\administrator\AppData\Local\Programs\Python\Python311\Lib\site-packages\mysql\connector\cursor_cext.py", line 330, in execute
    result = self._cnx.cmd_query(
             ^^^^^^^^^^^^^^^^^^^^
  File "C:\Users\administrator\AppData\Local\Programs\Python\Python311\Lib\site-packages\mysql\connector\connection_cext.py", line 619, in cmd_query
    raise get_mysql_exception(
mysql.connector.errors.ProgrammingError: 1146 (42S02): Table 'nttcs_cf.pruebaassess2' doesn't exist
[20/Jul/2023 10:41:39] "POST /MantenimientoAssessmentArchivados/ HTTP/1.1" 500 91223
[20/Jul/2023 10:41:54] "GET /menu/ HTTP/1.1" 200 9360
[20/Jul/2023 10:41:55] "GET /staticfiles/css/estilos.css HTTP/1.1" 304 0
[20/Jul/2023 10:41:56] "GET /assessmentselect/ HTTP/1.1" 200 21138
[20/Jul/2023 10:42:04] "GET /assessmentselect/ HTTP/1.1" 200 21138
[20/Jul/2023 10:42:08] "POST /assessmentselect/ HTTP/1.1" 302 0
[20/Jul/2023 10:42:08] "GET /assessment/ HTTP/1.1" 200 81630
[20/Jul/2023 10:42:13] "GET /assessmentselect/ HTTP/1.1" 200 21138
[20/Jul/2023 10:42:29] "POST /assessmentselect/ HTTP/1.1" 302 0
Internal Server Error: /assessment/
Traceback (most recent call last):
  File "C:\Users\administrator\AppData\Local\Programs\Python\Python311\Lib\site-packages\mysql\connector\connection_cext.py", line 416, in get_rows
    row = fetch_row()
          ^^^^^^^^^^^
_mysql_connector.MySQLInterfaceError: Table definition has changed, please retry transaction

The above exception was the direct cause of the following exception:

Traceback (most recent call last):
  File "C:\Users\administrator\AppData\Local\Programs\Python\Python311\Lib\site-packages\django\core\handlers\exception.py", line 55, in inner
    response = get_response(request)
               ^^^^^^^^^^^^^^^^^^^^^
  File "C:\Users\administrator\AppData\Local\Programs\Python\Python311\Lib\site-packages\django\core\handlers\base.py", line 197, in _get_response
    response = wrapped_callback(request, *callback_args, **callback_kwargs)
               ^^^^^^^^^^^^^^^^^^^^^^^^^^^^^^^^^^^^^^^^^^^^^^^^^^^^^^^^^^^^
  File "C:\Users\administrator\AppData\Local\Programs\Python\Python311\Lib\site-packages\django\views\generic\base.py", line 104, in view
    return self.dispatch(request, *args, **kwargs)
           ^^^^^^^^^^^^^^^^^^^^^^^^^^^^^^^^^^^^^^^
  File "C:\Users\administrator\AppData\Local\Programs\Python\Python311\Lib\site-packages\django\contrib\auth\mixins.py", line 73, in dispatch
    return super().dispatch(request, *args, **kwargs)
           ^^^^^^^^^^^^^^^^^^^^^^^^^^^^^^^^^^^^^^^^^^
  File "C:\Users\administrator\AppData\Local\Programs\Python\Python311\Lib\site-packages\django\views\generic\base.py", line 143, in dispatch
    return handler(request, *args, **kwargs)
           ^^^^^^^^^^^^^^^^^^^^^^^^^^^^^^^^^
  File "C:\Users\administrator\AppData\Local\Programs\Python\Python311\Lib\site-packages\django\views\generic\base.py", line 226, in get
    context = self.get_context_data(**kwargs)
              ^^^^^^^^^^^^^^^^^^^^^^^^^^^^^^^
  File "C:\Users\administrator\Documents\NTTCS_Control_Framework\NTTCS_CF_project\homepage\views.py", line 281, in get_context_data
    mycursor.execute("SELECT * FROM " + assSelect)
  File "C:\Users\administrator\AppData\Local\Programs\Python\Python311\Lib\site-packages\mysql\connector\cursor_cext.py", line 342, in execute
    self._handle_result(result)
  File "C:\Users\administrator\AppData\Local\Programs\Python\Python311\Lib\site-packages\mysql\connector\cursor_cext.py", line 230, in _handle_result
    self._handle_resultset()
  File "C:\Users\administrator\AppData\Local\Programs\Python\Python311\Lib\site-packages\mysql\connector\cursor_cext.py", line 788, in _handle_resultset
    self._rows = self._cnx.get_rows()[0]
                 ^^^^^^^^^^^^^^^^^^^^
  File "C:\Users\administrator\AppData\Local\Programs\Python\Python311\Lib\site-packages\mysql\connector\connection_cext.py", line 445, in get_rows
    raise get_mysql_exception(
mysql.connector.errors.DatabaseError: 1412 (HY000): Table definition has changed, please retry transaction
[20/Jul/2023 10:42:30] "GET /assessment/ HTTP/1.1" 500 105289
[20/Jul/2023 10:42:46] "POST /assessmentselect/ HTTP/1.1" 302 0
Internal Server Error: /assessment/
Traceback (most recent call last):
  File "C:\Users\administrator\AppData\Local\Programs\Python\Python311\Lib\site-packages\mysql\connector\connection_cext.py", line 416, in get_rows
    row = fetch_row()
          ^^^^^^^^^^^
_mysql_connector.MySQLInterfaceError: Table definition has changed, please retry transaction

The above exception was the direct cause of the following exception:

Traceback (most recent call last):
  File "C:\Users\administrator\AppData\Local\Programs\Python\Python311\Lib\site-packages\django\core\handlers\exception.py", line 55, in inner
    response = get_response(request)
               ^^^^^^^^^^^^^^^^^^^^^
  File "C:\Users\administrator\AppData\Local\Programs\Python\Python311\Lib\site-packages\django\core\handlers\base.py", line 197, in _get_response
    response = wrapped_callback(request, *callback_args, **callback_kwargs)
               ^^^^^^^^^^^^^^^^^^^^^^^^^^^^^^^^^^^^^^^^^^^^^^^^^^^^^^^^^^^^
  File "C:\Users\administrator\AppData\Local\Programs\Python\Python311\Lib\site-packages\django\views\generic\base.py", line 104, in view
    return self.dispatch(request, *args, **kwargs)
           ^^^^^^^^^^^^^^^^^^^^^^^^^^^^^^^^^^^^^^^
  File "C:\Users\administrator\AppData\Local\Programs\Python\Python311\Lib\site-packages\django\contrib\auth\mixins.py", line 73, in dispatch
    return super().dispatch(request, *args, **kwargs)
           ^^^^^^^^^^^^^^^^^^^^^^^^^^^^^^^^^^^^^^^^^^
  File "C:\Users\administrator\AppData\Local\Programs\Python\Python311\Lib\site-packages\django\views\generic\base.py", line 143, in dispatch
    return handler(request, *args, **kwargs)
           ^^^^^^^^^^^^^^^^^^^^^^^^^^^^^^^^^
  File "C:\Users\administrator\AppData\Local\Programs\Python\Python311\Lib\site-packages\django\views\generic\base.py", line 226, in get
    context = self.get_context_data(**kwargs)
              ^^^^^^^^^^^^^^^^^^^^^^^^^^^^^^^
  File "C:\Users\administrator\Documents\NTTCS_Control_Framework\NTTCS_CF_project\homepage\views.py", line 281, in get_context_data
    mycursor.execute("SELECT * FROM " + assSelect)
  File "C:\Users\administrator\AppData\Local\Programs\Python\Python311\Lib\site-packages\mysql\connector\cursor_cext.py", line 342, in execute
    self._handle_result(result)
  File "C:\Users\administrator\AppData\Local\Programs\Python\Python311\Lib\site-packages\mysql\connector\cursor_cext.py", line 230, in _handle_result
    self._handle_resultset()
  File "C:\Users\administrator\AppData\Local\Programs\Python\Python311\Lib\site-packages\mysql\connector\cursor_cext.py", line 788, in _handle_resultset
    self._rows = self._cnx.get_rows()[0]
                 ^^^^^^^^^^^^^^^^^^^^
  File "C:\Users\administrator\AppData\Local\Programs\Python\Python311\Lib\site-packages\mysql\connector\connection_cext.py", line 445, in get_rows
    raise get_mysql_exception(
mysql.connector.errors.DatabaseError: 1412 (HY000): Table definition has changed, please retry transaction
[20/Jul/2023 10:42:46] "GET /assessment/ HTTP/1.1" 500 105032
[20/Jul/2023 10:43:24] "GET /assessmentselect/ HTTP/1.1" 200 21344
[20/Jul/2023 10:43:29] "POST /assessmentselect/ HTTP/1.1" 302 0
Internal Server Error: /assessment/
Traceback (most recent call last):
  File "C:\Users\administrator\AppData\Local\Programs\Python\Python311\Lib\site-packages\mysql\connector\connection_cext.py", line 416, in get_rows
    row = fetch_row()
          ^^^^^^^^^^^
_mysql_connector.MySQLInterfaceError: Table definition has changed, please retry transaction

The above exception was the direct cause of the following exception:

Traceback (most recent call last):
  File "C:\Users\administrator\AppData\Local\Programs\Python\Python311\Lib\site-packages\django\core\handlers\exception.py", line 55, in inner
    response = get_response(request)
               ^^^^^^^^^^^^^^^^^^^^^
  File "C:\Users\administrator\AppData\Local\Programs\Python\Python311\Lib\site-packages\django\core\handlers\base.py", line 197, in _get_response
    response = wrapped_callback(request, *callback_args, **callback_kwargs)
               ^^^^^^^^^^^^^^^^^^^^^^^^^^^^^^^^^^^^^^^^^^^^^^^^^^^^^^^^^^^^
  File "C:\Users\administrator\AppData\Local\Programs\Python\Python311\Lib\site-packages\django\views\generic\base.py", line 104, in view
    return self.dispatch(request, *args, **kwargs)
           ^^^^^^^^^^^^^^^^^^^^^^^^^^^^^^^^^^^^^^^
  File "C:\Users\administrator\AppData\Local\Programs\Python\Python311\Lib\site-packages\django\contrib\auth\mixins.py", line 73, in dispatch
    return super().dispatch(request, *args, **kwargs)
           ^^^^^^^^^^^^^^^^^^^^^^^^^^^^^^^^^^^^^^^^^^
  File "C:\Users\administrator\AppData\Local\Programs\Python\Python311\Lib\site-packages\django\views\generic\base.py", line 143, in dispatch
    return handler(request, *args, **kwargs)
           ^^^^^^^^^^^^^^^^^^^^^^^^^^^^^^^^^
  File "C:\Users\administrator\AppData\Local\Programs\Python\Python311\Lib\site-packages\django\views\generic\base.py", line 226, in get
    context = self.get_context_data(**kwargs)
              ^^^^^^^^^^^^^^^^^^^^^^^^^^^^^^^
  File "C:\Users\administrator\Documents\NTTCS_Control_Framework\NTTCS_CF_project\homepage\views.py", line 281, in get_context_data
    mycursor.execute("SELECT * FROM " + assSelect)
  File "C:\Users\administrator\AppData\Local\Programs\Python\Python311\Lib\site-packages\mysql\connector\cursor_cext.py", line 342, in execute
    self._handle_result(result)
  File "C:\Users\administrator\AppData\Local\Programs\Python\Python311\Lib\site-packages\mysql\connector\cursor_cext.py", line 230, in _handle_result
    self._handle_resultset()
  File "C:\Users\administrator\AppData\Local\Programs\Python\Python311\Lib\site-packages\mysql\connector\cursor_cext.py", line 788, in _handle_resultset
    self._rows = self._cnx.get_rows()[0]
                 ^^^^^^^^^^^^^^^^^^^^
  File "C:\Users\administrator\AppData\Local\Programs\Python\Python311\Lib\site-packages\mysql\connector\connection_cext.py", line 445, in get_rows
    raise get_mysql_exception(
mysql.connector.errors.DatabaseError: 1412 (HY000): Table definition has changed, please retry transaction
[20/Jul/2023 10:43:29] "GET /assessment/ HTTP/1.1" 500 105032
[20/Jul/2023 10:43:47] "GET /assessmentselect/ HTTP/1.1" 200 21344
[20/Jul/2023 10:43:49] "GET /assessmentselect/ HTTP/1.1" 200 21344
[20/Jul/2023 10:43:51] "POST /assessmentselect/ HTTP/1.1" 302 0
Internal Server Error: /assessment/
Traceback (most recent call last):
  File "C:\Users\administrator\AppData\Local\Programs\Python\Python311\Lib\site-packages\mysql\connector\connection_cext.py", line 416, in get_rows
    row = fetch_row()
          ^^^^^^^^^^^
_mysql_connector.MySQLInterfaceError: Table definition has changed, please retry transaction

The above exception was the direct cause of the following exception:

Traceback (most recent call last):
  File "C:\Users\administrator\AppData\Local\Programs\Python\Python311\Lib\site-packages\django\core\handlers\exception.py", line 55, in inner
    response = get_response(request)
               ^^^^^^^^^^^^^^^^^^^^^
  File "C:\Users\administrator\AppData\Local\Programs\Python\Python311\Lib\site-packages\django\core\handlers\base.py", line 197, in _get_response
    response = wrapped_callback(request, *callback_args, **callback_kwargs)
               ^^^^^^^^^^^^^^^^^^^^^^^^^^^^^^^^^^^^^^^^^^^^^^^^^^^^^^^^^^^^
  File "C:\Users\administrator\AppData\Local\Programs\Python\Python311\Lib\site-packages\django\views\generic\base.py", line 104, in view
    return self.dispatch(request, *args, **kwargs)
           ^^^^^^^^^^^^^^^^^^^^^^^^^^^^^^^^^^^^^^^
  File "C:\Users\administrator\AppData\Local\Programs\Python\Python311\Lib\site-packages\django\contrib\auth\mixins.py", line 73, in dispatch
    return super().dispatch(request, *args, **kwargs)
           ^^^^^^^^^^^^^^^^^^^^^^^^^^^^^^^^^^^^^^^^^^
  File "C:\Users\administrator\AppData\Local\Programs\Python\Python311\Lib\site-packages\django\views\generic\base.py", line 143, in dispatch
    return handler(request, *args, **kwargs)
           ^^^^^^^^^^^^^^^^^^^^^^^^^^^^^^^^^
  File "C:\Users\administrator\AppData\Local\Programs\Python\Python311\Lib\site-packages\django\views\generic\base.py", line 226, in get
    context = self.get_context_data(**kwargs)
              ^^^^^^^^^^^^^^^^^^^^^^^^^^^^^^^
  File "C:\Users\administrator\Documents\NTTCS_Control_Framework\NTTCS_CF_project\homepage\views.py", line 281, in get_context_data
    mycursor.execute("SELECT * FROM " + assSelect)
  File "C:\Users\administrator\AppData\Local\Programs\Python\Python311\Lib\site-packages\mysql\connector\cursor_cext.py", line 342, in execute
    self._handle_result(result)
  File "C:\Users\administrator\AppData\Local\Programs\Python\Python311\Lib\site-packages\mysql\connector\cursor_cext.py", line 230, in _handle_result
    self._handle_resultset()
  File "C:\Users\administrator\AppData\Local\Programs\Python\Python311\Lib\site-packages\mysql\connector\cursor_cext.py", line 788, in _handle_resultset
    self._rows = self._cnx.get_rows()[0]
                 ^^^^^^^^^^^^^^^^^^^^
  File "C:\Users\administrator\AppData\Local\Programs\Python\Python311\Lib\site-packages\mysql\connector\connection_cext.py", line 445, in get_rows
    raise get_mysql_exception(
mysql.connector.errors.DatabaseError: 1412 (HY000): Table definition has changed, please retry transaction
[20/Jul/2023 10:43:51] "GET /assessment/ HTTP/1.1" 500 105289
[20/Jul/2023 10:44:36] "POST /assessmentselect/ HTTP/1.1" 302 0
Internal Server Error: /assessment/
Traceback (most recent call last):
  File "C:\Users\administrator\AppData\Local\Programs\Python\Python311\Lib\site-packages\mysql\connector\connection_cext.py", line 416, in get_rows
    row = fetch_row()
          ^^^^^^^^^^^
_mysql_connector.MySQLInterfaceError: Table definition has changed, please retry transaction

The above exception was the direct cause of the following exception:

Traceback (most recent call last):
  File "C:\Users\administrator\AppData\Local\Programs\Python\Python311\Lib\site-packages\django\core\handlers\exception.py", line 55, in inner
    response = get_response(request)
               ^^^^^^^^^^^^^^^^^^^^^
  File "C:\Users\administrator\AppData\Local\Programs\Python\Python311\Lib\site-packages\django\core\handlers\base.py", line 197, in _get_response
    response = wrapped_callback(request, *callback_args, **callback_kwargs)
               ^^^^^^^^^^^^^^^^^^^^^^^^^^^^^^^^^^^^^^^^^^^^^^^^^^^^^^^^^^^^
  File "C:\Users\administrator\AppData\Local\Programs\Python\Python311\Lib\site-packages\django\views\generic\base.py", line 104, in view
    return self.dispatch(request, *args, **kwargs)
           ^^^^^^^^^^^^^^^^^^^^^^^^^^^^^^^^^^^^^^^
  File "C:\Users\administrator\AppData\Local\Programs\Python\Python311\Lib\site-packages\django\contrib\auth\mixins.py", line 73, in dispatch
    return super().dispatch(request, *args, **kwargs)
           ^^^^^^^^^^^^^^^^^^^^^^^^^^^^^^^^^^^^^^^^^^
  File "C:\Users\administrator\AppData\Local\Programs\Python\Python311\Lib\site-packages\django\views\generic\base.py", line 143, in dispatch
    return handler(request, *args, **kwargs)
           ^^^^^^^^^^^^^^^^^^^^^^^^^^^^^^^^^
  File "C:\Users\administrator\AppData\Local\Programs\Python\Python311\Lib\site-packages\django\views\generic\base.py", line 226, in get
    context = self.get_context_data(**kwargs)
              ^^^^^^^^^^^^^^^^^^^^^^^^^^^^^^^
  File "C:\Users\administrator\Documents\NTTCS_Control_Framework\NTTCS_CF_project\homepage\views.py", line 281, in get_context_data
    mycursor.execute("SELECT * FROM " + assSelect)
  File "C:\Users\administrator\AppData\Local\Programs\Python\Python311\Lib\site-packages\mysql\connector\cursor_cext.py", line 342, in execute
    self._handle_result(result)
  File "C:\Users\administrator\AppData\Local\Programs\Python\Python311\Lib\site-packages\mysql\connector\cursor_cext.py", line 230, in _handle_result
    self._handle_resultset()
  File "C:\Users\administrator\AppData\Local\Programs\Python\Python311\Lib\site-packages\mysql\connector\cursor_cext.py", line 788, in _handle_resultset
    self._rows = self._cnx.get_rows()[0]
                 ^^^^^^^^^^^^^^^^^^^^
  File "C:\Users\administrator\AppData\Local\Programs\Python\Python311\Lib\site-packages\mysql\connector\connection_cext.py", line 445, in get_rows
    raise get_mysql_exception(
mysql.connector.errors.DatabaseError: 1412 (HY000): Table definition has changed, please retry transaction
[20/Jul/2023 10:44:36] "GET /assessment/ HTTP/1.1" 500 105053
[20/Jul/2023 10:45:53] "GET / HTTP/1.1" 200 1515
Not Found: /payment/index.php
[20/Jul/2023 10:45:53] "GET /payment/index.php HTTP/1.1" 404 6529
C:\Users\administrator\Documents\NTTCS_Control_Framework\NTTCS_CF_project\homepage\views.py changed, reloading.
Performing system checks...

System check identified no issues (0 silenced).
July 20, 2023 - 10:38:57
Django version 4.2.2, using settings 'NTTCS_CF_project.settings'
Starting development server at http://127.0.0.1:9242/
Quit the server with CTRL-BREAK.

Watching for file changes with StatReloader
[20/Jul/2023 10:46:57] "GET /usuarios/ HTTP/1.1" 200 15690
[20/Jul/2023 10:46:59] "GET /assessmentselect/ HTTP/1.1" 200 21454
[20/Jul/2023 10:47:03] "POST /assessmentselect/ HTTP/1.1" 302 0
[20/Jul/2023 10:47:03] "GET /assessment/ HTTP/1.1" 200 44505
[20/Jul/2023 10:47:11] "GET /assessmentselect/ HTTP/1.1" 200 21454
[20/Jul/2023 10:49:42] "GET /assessmentselect/ HTTP/1.1" 200 21454
C:\Users\administrator\Documents\NTTCS_Control_Framework\NTTCS_CF_project\homepage\views.py changed, reloading.
Performing system checks...

System check identified no issues (0 silenced).
July 20, 2023 - 10:46:54
Django version 4.2.2, using settings 'NTTCS_CF_project.settings'
Starting development server at http://127.0.0.1:9242/
Quit the server with CTRL-BREAK.

Watching for file changes with StatReloader
[20/Jul/2023 10:49:51] "GET /assessmentselect/ HTTP/1.1" 200 21454
[20/Jul/2023 10:49:51] "GET /menu/ HTTP/1.1" 200 9360
[20/Jul/2023 10:49:52] "GET /assessmentselect/ HTTP/1.1" 200 21454
Internal Server Error: /assessmentselect/
Traceback (most recent call last):
  File "C:\Users\administrator\AppData\Local\Programs\Python\Python311\Lib\site-packages\mysql\connector\connection_cext.py", line 611, in cmd_query
    self._cmysql.query(
_mysql_connector.MySQLInterfaceError: Table 'pruebaassess4' already exists

The above exception was the direct cause of the following exception:

Traceback (most recent call last):
  File "C:\Users\administrator\AppData\Local\Programs\Python\Python311\Lib\site-packages\django\core\handlers\exception.py", line 55, in inner
    response = get_response(request)
               ^^^^^^^^^^^^^^^^^^^^^
  File "C:\Users\administrator\AppData\Local\Programs\Python\Python311\Lib\site-packages\django\core\handlers\base.py", line 197, in _get_response
    response = wrapped_callback(request, *callback_args, **callback_kwargs)
               ^^^^^^^^^^^^^^^^^^^^^^^^^^^^^^^^^^^^^^^^^^^^^^^^^^^^^^^^^^^^
  File "C:\Users\administrator\AppData\Local\Programs\Python\Python311\Lib\site-packages\django\views\generic\base.py", line 104, in view
    return self.dispatch(request, *args, **kwargs)
           ^^^^^^^^^^^^^^^^^^^^^^^^^^^^^^^^^^^^^^^
  File "C:\Users\administrator\AppData\Local\Programs\Python\Python311\Lib\site-packages\django\contrib\auth\mixins.py", line 73, in dispatch
    return super().dispatch(request, *args, **kwargs)
           ^^^^^^^^^^^^^^^^^^^^^^^^^^^^^^^^^^^^^^^^^^
  File "C:\Users\administrator\AppData\Local\Programs\Python\Python311\Lib\site-packages\django\views\generic\base.py", line 143, in dispatch
    return handler(request, *args, **kwargs)
           ^^^^^^^^^^^^^^^^^^^^^^^^^^^^^^^^^
  File "C:\Users\administrator\Documents\NTTCS_Control_Framework\NTTCS_CF_project\homepage\views.py", line 448, in post
    mycursor.execute(query)
  File "C:\Users\administrator\AppData\Local\Programs\Python\Python311\Lib\site-packages\mysql\connector\cursor_cext.py", line 330, in execute
    result = self._cnx.cmd_query(
             ^^^^^^^^^^^^^^^^^^^^
  File "C:\Users\administrator\AppData\Local\Programs\Python\Python311\Lib\site-packages\mysql\connector\connection_cext.py", line 619, in cmd_query
    raise get_mysql_exception(
mysql.connector.errors.ProgrammingError: 1050 (42S01): Table 'pruebaassess4' already exists
[20/Jul/2023 10:50:08] "POST /assessmentselect/ HTTP/1.1" 500 95429
[20/Jul/2023 10:50:14] "GET /assessmentselect/ HTTP/1.1" 200 21454
[20/Jul/2023 10:50:33] "GET /informes/ HTTP/1.1" 200 9384
[20/Jul/2023 10:50:36] "GET /assessmentselect/ HTTP/1.1" 200 21454
[20/Jul/2023 10:51:43] "POST /assessmentselect/ HTTP/1.1" 302 0
[20/Jul/2023 10:51:43] "GET /assessment/ HTTP/1.1" 200 86875
[20/Jul/2023 10:51:55] "GET /assessmentselect/ HTTP/1.1" 200 21564
C:\Users\administrator\Documents\NTTCS_Control_Framework\NTTCS_CF_project\homepage\views.py changed, reloading.
Performing system checks...

System check identified no issues (0 silenced).
July 20, 2023 - 10:49:51
Django version 4.2.2, using settings 'NTTCS_CF_project.settings'
Starting development server at http://127.0.0.1:9242/
Quit the server with CTRL-BREAK.

Watching for file changes with StatReloader
[20/Jul/2023 10:52:20] "POST /assessmentselect/ HTTP/1.1" 302 0
[20/Jul/2023 10:52:20] "GET /assessment/ HTTP/1.1" 200 86875
C:\Users\administrator\Documents\NTTCS_Control_Framework\NTTCS_CF_project\homepage\views.py changed, reloading.
Performing system checks...

System check identified no issues (0 silenced).
July 20, 2023 - 10:51:58
Django version 4.2.2, using settings 'NTTCS_CF_project.settings'
Starting development server at http://127.0.0.1:9242/
Quit the server with CTRL-BREAK.

Watching for file changes with StatReloader
[20/Jul/2023 10:53:14] "GET /assessmentselect/ HTTP/1.1" 200 21674
[20/Jul/2023 10:53:32] "POST /assessmentselect/ HTTP/1.1" 302 0
[20/Jul/2023 10:53:32] "GET /assessment/ HTTP/1.1" 200 86875
[20/Jul/2023 10:53:41] "GET /assessmentselect/ HTTP/1.1" 200 21784
C:\Users\administrator\Documents\NTTCS_Control_Framework\NTTCS_CF_project\homepage\views.py changed, reloading.
Performing system checks...

System check identified no issues (0 silenced).
July 20, 2023 - 10:53:14
Django version 4.2.2, using settings 'NTTCS_CF_project.settings'
Starting development server at http://127.0.0.1:9242/
Quit the server with CTRL-BREAK.

Watching for file changes with StatReloader
[20/Jul/2023 10:54:14] "POST /assessmentselect/ HTTP/1.1" 302 0
[20/Jul/2023 10:54:14] "GET /assessment/ HTTP/1.1" 200 86875
[20/Jul/2023 10:54:24] "GET /assessmentselect/ HTTP/1.1" 200 21894
C:\Users\administrator\Documents\NTTCS_Control_Framework\NTTCS_CF_project\homepage\views.py changed, reloading.
Performing system checks...

System check identified no issues (0 silenced).
July 20, 2023 - 10:53:56
Django version 4.2.2, using settings 'NTTCS_CF_project.settings'
Starting development server at http://127.0.0.1:9242/
Quit the server with CTRL-BREAK.

Watching for file changes with StatReloader
[20/Jul/2023 10:54:46] "POST /assessmentselect/ HTTP/1.1" 302 0
[20/Jul/2023 10:54:46] "GET /assessment/ HTTP/1.1" 200 85406
[20/Jul/2023 10:55:26] "GET /assessmentselect/ HTTP/1.1" 200 22004
[20/Jul/2023 10:55:29] "POST /assessmentselect/ HTTP/1.1" 302 0
[20/Jul/2023 10:55:29] "GET /assessment/ HTTP/1.1" 200 44505
[20/Jul/2023 10:55:31] "GET /assessmentselect/ HTTP/1.1" 200 22004
[20/Jul/2023 10:55:34] "POST /assessmentselect/ HTTP/1.1" 302 0
[20/Jul/2023 10:55:34] "GET /assessment/ HTTP/1.1" 200 85406
[20/Jul/2023 10:55:39] "POST /assessment/ HTTP/1.1" 200 88734
[20/Jul/2023 10:55:51] "POST /assessment/ HTTP/1.1" 302 0
[20/Jul/2023 10:55:51] "GET /menu/ HTTP/1.1" 200 9360
[20/Jul/2023 10:55:53] "GET /MantenimientoAssessmentArchivados/ HTTP/1.1" 200 10068
[20/Jul/2023 10:55:56] "POST /MantenimientoAssessmentArchivados/ HTTP/1.1" 200 3349815
[20/Jul/2023 10:56:25] "POST /MantenimientoAssessmentArchivados/ HTTP/1.1" 200 3349815
[20/Jul/2023 10:56:26] "GET /staticfiles/css/ass.css HTTP/1.1" 200 6958
[20/Jul/2023 10:56:26] "GET /staticfiles/css/estilos.css HTTP/1.1" 200 5831
[20/Jul/2023 10:56:26] "GET /staticfiles/js/scripts.js HTTP/1.1" 200 1798
[20/Jul/2023 10:56:26] "GET /staticfiles/images/logo_NTTData.jpg HTTP/1.1" 200 2121
[20/Jul/2023 10:56:26] "GET /staticfiles/images/logo_NTTCS_CF.jpg HTTP/1.1" 200 20664
[20/Jul/2023 10:56:27] "GET /staticfiles/images/logo_NTTCS_CF.jpg HTTP/1.1" 200 20664
[20/Jul/2023 10:58:48] "GET /assessmentselect/ HTTP/1.1" 200 21894
[20/Jul/2023 10:58:49] "GET /MantenimientoAssessmentArchivados/ HTTP/1.1" 200 10068
